Workbook

Sheet Nasil_Kullanilir
A1: İç Denetim Standardizasyonu ve Bulgulardan Eğitim Programı
A2: Tüm mağaza, bulgu ve tarih verileri SAHTEDİR. Orijinal dosyalar paylaşılamadığı için yapı, sistemin nasıl çalıştığı hatırlanarak yeniden kurulmuştur.
A4: Akış
A5: 1. Denetim_Takvimi: çeyrek bazında karşılıklı iç denetim rotasyonu ve tahmini esas denetim tarihleri. Yakın mağazalar 3 ayda bir birbirini denetler; her müdür uzman olduğu denetim türüne gider.
A6: 2. Denetimler: iç ve esas denetimlerin her biri bir satır. Puan, Bulgular sayfasındaki kayıtlardan hesaplanır.
A7: 3. Bulgular: her uygunsuzluk bir satır; madde kodu seçilir, madde adı ve önem derecesi Madde_Listesi'nden gelir.
A8: 4. DOF_Takip: bulguya bağlı düzeltici-önleyici faaliyet, sorumlu, termin ve kapanış.
A9: 5. Dashboard: mağaza × denetim türü puanları (iç ve esas), iç-esas farkı, gecikmiş DÖF sayısı.
A10: 6. Oncelik_Listesi: en çok tekrar eden uygunsuzluklar, önem derecesiyle ağırlıklı; her maddenin eğitim konusu ve en sık görüldüğü mağaza. Eğitim programı bu listeden hazırlanır.
A11: 7. Madde_Magaza: madde × mağaza tekrar matrisi; hangi mağazada hangi maddenin tekrarlandığını gösterir.
A13: Puan hesabı
A14: Ceza = kritik × 2 + major × 1,5 + minör × 1 (katsayılar Ayarlar'da). Puan = (toplam soru − ceza) ÷ toplam soru × 100.
... A17: Renk kodu: mavi = girilen değer · sarı zemin = güncellenen hücre · siyah = formül · yeşil = başka sayfadan gelen değer

Sheet Dashboard
A1: Denetim Dashboard
A2: Puanlar yıl içindeki denetimlerin ortalamasıdır. Fark = iç denetim − esas denetim; büyük pozitif fark iç denetimin gerçeği yansıtmadığına işaret eder.
A4: Mağaza | B4: ASA İç | C4: ASA Esas | D4: ASA Fark | E4: PAP İç | F4: PAP Esas | G4: PAP Fark | H4: RSA İç | I4: RSA Esas | J4: RSA Fark | K4: Esas Ortalama | L4: Sıra | M4: Toplam Bulgu | N4: Kritik Bulgu | O4: Açık DÖF | P4: Gecikmiş DÖF
A5: =Magazalar!A2 -> Mağaza A | B5: =IFERROR(AVERAGEIFS(Denetimler!$L$2:$L$286,Denetimler!$C$2:$C$286,$A5,Denetimler!$D$2:$D$286,"ASA",Denetimler!$E$2:$E$286,"İç denetim"),"") -> 89.375 | C5: =IFERROR(AVERAGEIFS(Denetimler!$L$2:$L$286,Denetimler!$C$2:$C$286,$A5,Denetimler!$D$2:$D$286,"ASA",Denetimler!$E$2:$E$286,"Esas denetim"),"") -> 86.25 | D5: =IF(OR(B5="",C5=""),"",B5-C5) -> 3.125 | E5: =IFERROR(AVERAGEIFS(Denetimler!$L$2:$L$286,Denetimler!$C$2:$C$286,$A5,Denetimler!$D$2:$D$286,"PAP",Denetimler!$E$2:$E$286,"İç denetim"),"") -> 96.111111 | F5: =IFERROR(AVERAGEIFS(Denetimler!$L$2:$L$286,Denetimler!$C$2:$C$286,$A5,Denetimler!$D$2:$D$286,"PAP",Denetimler!$E$2:$E$286,"Esas denetim"),"") -> 90 | G5: =IF(OR(E5="",F5=""),"",E5-F5) -> 6.1111111 | H5: =IFERROR(AVERAGEIFS(Denetimler!$L$2:$L$286,Denetimler!$C$2:$C$286,$A5,Denetimler!$D$2:$D$286,"RSA",Denetimler!$E$2:$E$286,"İç denetim"),"") -> 92.032967 | I5: =IFERROR(AVERAGEIFS(Denetimler!$L$2:$L$286,Denetimler!$C$2:$C$286,$A5,Denetimler!$D$2:$D$286,"RSA",Denetimler!$E$2:$E$286,"Esas denetim"),"") -> 92.307692 | J5: =IF(OR(H5="",I5=""),"",H5-I5) -> -0.27472527 | K5: =IFERROR(AVERAGE(C5,F5,I5),"") -> 89.519231 | L5: =IFERROR(RANK(K5,$K$5:$K$12),"") -> 3 | M5: =COUNTIF(Bulgular!$H$2:$H$570,A5) -> 27 | N5: =COUNTIFS(Bulgular!$H$2:$H$570,A5,Bulgular!$F$2:$F$570,"Kritik") -> 6 | O5: =COUNTIFS(DOF_Takip!$C$2:$C$200,A5,DOF_Takip!$J$2:$J$200,"Açık")+COUNTIFS(DOF_Takip!$C$2:$C$200,A5,DOF_Takip!$J$2:$J$200,"Gecikmiş") -> 0 | P5: =COUNTIFS(DOF_Takip!$C$2:$C$200,A5,DOF_Takip!$J$2:$J$200,"Gecikmiş") -> 0
A6: =Magazalar!A3 -> Mağaza B | B6: =IFERROR(AVERAGEIFS(Denetimler!$L$2:$L$286,Denetimler!$C$2:$C$286,$A6,Denetimler!$D$2:$D$286,"ASA",Denetimler!$E$2:$E$286,"İç denetim"),"") -> 90.625 | C6: =IFERROR(AVERAGEIFS(Denetimler!$L$2:$L$286,Denetimler!$C$2:$C$286,$A6,Denetimler!$D$2:$D$286,"ASA",Denetimler!$E$2:$E$286,"Esas denetim"),"") -> 96.25 | D6: =IF(OR(B6="",C6=""),"",B6-C6) -> -5.625 | E6: =IFERROR(AVERAGEIFS(Denetimler!$L$2:$L$286,Denetimler!$C$2:$C$286,$A6,Denetimler!$D$2:$D$286,"PAP",Denetimler!$E$2:$E$286,"İç denetim"),"") -> 86.666667 | F6: =IFERROR(AVERAGEIFS(Denetimler!$L$2:$L$286,Denetimler!$C$2:$C$286,$A6,Denetimler!$D$2:$D$286,"PAP",Denetimler!$E$2:$E$286,"Esas denetim"),"") -> 88.333333 | G6: =IF(OR(E6="",F6=""),"",E6-F6) -> -1.6666667 | H6: =IFERROR(AVERAGEIFS(Denetimler!$L$2:$L$286,Denetimler!$C$2:$C$286,$A6,Denetimler!$D$2:$D$286,"RSA",Denetimler!$E$2:$E$286,"İç denetim"),"") -> 94.230769 | I6: =IFERROR(AVERAGEIFS(Denetimler!$L$2:$L$286,Denetimler!$C$2:$C$286,$A6,Denetimler!$D$2:$D$286,"RSA",Denetimler!$E$2:$E$286,"Esas denetim"),"") -> 98.351648 | J6: =IF(OR(H6="",I6=""),"",H6-I6) -> -4.1208791 | K6: =IFERROR(AVERAGE(C6,F6,I6),"") -> 94.311661 | L6: =IFERROR(RANK(K6,$K$5:$K$12),"") -> 2 | M6: =COUNTIF(Bulgular!$H$2:$H$570,A6) -> 21 | N6: =COUNTIFS(Bulgular!$H$2:$H$570,A6,Bulgular!$F$2:$F$570,"Kritik") -> 6 | O6: =COUNTIFS(DOF_Takip!$C$2:$C$200,A6,DOF_Takip!$J$2:$J$200,"Açık")+COUNTIFS(DOF_Takip!$C$2:$C$200,A6,DOF_Takip!$J$2:$J$200,"Gecikmiş") -> 1 | P6: =COUNTIFS(DOF_Takip!$C$2:$C$200,A6,DOF_Takip!$J$2:$J$200,"Gecikmiş") -> 1
A7: =Magazalar!A4 -> Mağaza C | B7: =IFERROR(AVERAGEIFS(Denetimler!$L$2:$L$286,Denetimler!$C$2:$C$286,$A7,Denetimler!$D$2:$D$286,"ASA",Denetimler!$E$2:$E$286,"İç denetim"),"") -> 92.083333 | C7: =IFERROR(AVERAGEIFS(Denetimler!$L$2:$L$286,Denetimler!$C$2:$C$286,$A7,Denetimler!$D$2:$D$286,"ASA",Denetimler!$E$2:$E$286,"Esas denetim"),"") -> 96.25 | D7: =IF(OR(B7="",C7=""),"",B7-C7) -> -4.1666667 | E7: =IFERROR(AVERAGEIFS(Denetimler!$L$2:$L$286,Denetimler!$C$2:$C$286,$A7,Denetimler!$D$2:$D$286,"PAP",Denetimler!$E$2:$E$286,"İç denetim"),"") -> 91.666667 | F7: =IFERROR(AVERAGEIFS(Denetimler!$L$2:$L$286,Denetimler!$C$2:$C$286,$A7,Denetimler!$D$2:$D$286,"PAP",Denetimler!$E$2:$E$286,"Esas denetim"),"") -> 91.666667 | G7: =IF(OR(E7="",F7=""),"",E7-F7) -> 0 | H7: =IFERROR(AVERAGEIFS(Denetimler!$L$2:$L$286,Denetimler!$C$2:$C$286,$A7,Denetimler!$D$2:$D$286,"RSA",Denetimler!$E$2:$E$286,"İç denetim"),"") -> 93.589744 | I7: =IFERROR(AVERAGEIFS(Denetimler!$L$2:$L$286,Denetimler!$C$2:$C$286,$A7,Denetimler!$D$2:$D$286,"RSA",Denetimler!$E$2:$E$286,"Esas denetim"),"") -> 96.703297 | J7: =IF(OR(H7="",I7=""),"",H7-I7) -> -3.1135531 | K7: =IFERROR(AVERAGE(C7,F7,I7),"") -> 94.873321 | L7: =IFERROR(RANK(K7,$K$5:$K$12),"") -> 1 | M7: =COUNTIF(Bulgular!$H$2:$H$570,A7) -> 28 | N7: =COUNTIFS(Bulgular!$H$2:$H$570,A7,Bulgular!$F$2:$F$570,"Kritik") -> 4 | O7: =COUNTIFS(DOF_Takip!$C$2:$C$200,A7,DOF_Takip!$J$2:$J$200,"Açık")+COUNTIFS(DOF_Takip!$C$2:$C$200,A7,DOF_Takip!$J$2:$J$200,"Gecikmiş") -> 0 | P7: =COUNTIFS(DOF_Takip!$C$2:$C$200,A7,DOF_Takip!$J$2:$J$200,"Gecikmiş") -> 0
A8: =Magazalar!A5 -> Mağaza D | B8: =IFERROR(AVERAGEIFS(Denetimler!$L$2:$L$286,Denetimler!$C$2:$C$286,$A8,Denetimler!$D$2:$D$286,"ASA",Denetimler!$E$2:$E$286,"İç denetim"),"") -> 86.875 | C8: =IFERROR(AVERAGEIFS(Denetimler!$L$2:$L$286,Denetimler!$C$2:$C$286,$A8,Denetimler!$D$2:$D$286,"ASA",Denetimler!$E$2:$E$286,"Esas denetim"),"") -> 96.25 | D8: =IF(OR(B8="",C8=""),"",B8-C8) -> -9.375 | E8: =IFERROR(AVERAGEIFS(Denetimler!$L$2:$L$286,Denetimler!$C$2:$C$286,$A8,Denetimler!$D$2:$D$286,"PAP",Denetimler!$E$2:$E$286,"İç denetim"),"") -> 78.333333 | F8: =IFERROR(AVERAGEIFS(Denetimler!$L$2:$L$286,Denetimler!$C$2:$C$286,$A8,Denetimler!$D$2:$D$286,"PAP",Denetimler!$E$2:$E$286,"Esas denetim"),"") -> 75 | G8: =IF(OR(E8="",F8=""),"",E8-F8) -> 3.3333333 | H8: =IFERROR(AVERAGEIFS(Denetimler!$L$2:$L$286,Denetimler!$C$2:$C$286,$A8,Denetimler!$D$2:$D$286,"RSA",Denetimler!$E$2:$E$286,"İç denetim"),"") -> 94.688645 | I8: =IFERROR(AVERAGEIFS(Denetimler!$L$2:$L$286,Denetimler!$C$2:$C$286,$A8,Denetimler!$D$2:$D$286,"RSA",Denetimler!$E$2:$E$286,"Esas denetim"),"") -> 96.153846 | J8: =IF(OR(H8="",I8=""),"",H8-I8) -> -1.4652015 | K8: =IFERROR(AVERAGE(C8,F8,I8),"") -> 89.134615 | L8: =IFERROR(RANK(K8,$K$5:$K$12),"") -> 4 | M8: =COUNTIF(Bulgular!$H$2:$H$570,A8) -> 38 | N8: =COUNTIFS(Bulgular!$H$2:$H$570,A8,Bulgular!$F$2:$F$570,"Kritik") -> 4 | O8: =COUNTIFS(DOF_Takip!$C$2:$C$200,A8,DOF_Takip!$J$2:$J$200,"Açık")+COUNTIFS(DOF_Takip!$C$2:$C$200,A8,DOF_Takip!$J$2:$J$200,"Gecikmiş") -> 3 | P8: =COUNTIFS(DOF_Takip!$C$2:$C$200,A8,DOF_Takip!$J$2:$J$200,"Gecikmiş") -> 3
A9: =Magazalar!A6 -> Mağaza E | B9: =IFERROR(AVERAGEIFS(Denetimler!$L$2:$L$286,Denetimler!$C$2:$C$286,$A9,Denetimler!$D$2:$D$286,"ASA",Denetimler!$E$2:$E$286,"İç denetim"),"") -> 95.416667 | C9: =IFERROR(AVERAGEIFS(Denetimler!$L$2:$L$286,Denetimler!$C$2:$C$286,$A9,Denetimler!$D$2:$D$286,"ASA",Denetimler!$E$2:$E$286,"Esas denetim"),"") -> 83.75 | D9: =IF(OR(B9="",C9=""),"",B9-C9) -> 11.666667 | E9: =IFERROR(AVERAGEIFS(Denetimler!$L$2:$L$286,Denetimler!$C$2:$C$286,$A9,Denetimler!$D$2:$D$286,"PAP",Denetimler!$E$2:$E$286,"İç denetim"),"") -> 89.444444 | F9: =IFERROR(AVERAGEIFS(Denetimler!$L$2:$L$286,Denetimler!$C$2:$C$286,$A9,Denetimler!$D$2:$D$286,"PAP",Denetimler!$E$2:$E$286,"Esas denetim"),"") -> 78.333333 | G9: =IF(OR(E9="",F9=""),"",E9-F9) -> 11.111111 | H9: =IFERROR(AVERAGEIFS(Denetimler!$L$2:$L$286,Denetimler!$C$2:$C$286,$A9,Denetimler!$D$2:$D$286,"RSA",Denetimler!$E$2:$E$286,"İç denetim"),"") -> 97.527473 | I9: =IFERROR(AVERAGEIFS(Denetimler!$L$2:$L$286,Denetimler!$C$2:$C$286,$A9,Denetimler!$D$2:$D$286,"RSA",Denetimler!$E$2:$E$286,"Esas denetim"),"") -> 91.208791 | J9: =IF(OR(H9="",I9=""),"",H9-I9) -> 6.3186813 | K9: =IFERROR(AVERAGE(C9,F9,I9),"") -> 84.430708 | L9: =IFERROR(RANK(K9,$K$5:$K$12),"") -> 6 | M9: =COUNTIF(Bulgular!$H$2:$H$570,A9) -> 27 | N9: =COUNTIFS(Bulgular!$H$2:$H$570,A9,Bulgular!$F$2:$F$570,"Kritik") -> 5 | O9: =COUNTIFS(DOF_Takip!$C$2:$C$200,A9,DOF_Takip!$J$2:$J$200,"Açık")+COUNTIFS(DOF_Takip!$C$2:$C$200,A9,DOF_Takip!$J$2:$J$200,"Gecikmiş") -> 1 | P9: =COUNTIFS(DOF_Takip!$C$2:$C$200,A9,DOF_Takip!$J$2:$J$200,"Gecikmiş") -> 1
A10: =Magazalar!A7 -> Mağaza F | B10: =IFERROR(AVERAGEIFS(Denetimler!$L$2:$L$286,Denetimler!$C$2:$C$286,$A10,Denetimler!$D$2:$D$286,"ASA",Denetimler!$E$2:$E$286,"İç denetim"),"") -> 93.333333 | C10: =IFERROR(AVERAGEIFS(Denetimler!$L$2:$L$286,Denetimler!$C$2:$C$286,$A10,Denetimler!$D$2:$D$286,"ASA",Denetimler!$E$2:$E$286,"Esas denetim"),"") -> 72.5 | D10: =IF(OR(B10="",C10=""),"",B10-C10) -> 20.833333 | E10: =IFERROR(AVERAGEIFS(Denetimler!$L$2:$L$286,Denetimler!$C$2:$C$286,$A10,Denetimler!$D$2:$D$286,"PAP",Denetimler!$E$2:$E$286,"İç denetim"),"") -> 79.444444 | F10: =IFERROR(AVERAGEIFS(Denetimler!$L$2:$L$286,Denetimler!$C$2:$C$286,$A10,Denetimler!$D$2:$D$286,"PAP",Denetimler!$E$2:$E$286,"Esas denetim"),"") -> 80 | G10: =IF(OR(E10="",F10=""),"",E10-F10) -> -0.55555556 | H10: =IFERROR(AVERAGEIFS(Denetimler!$L$2:$L$286,Denetimler!$C$2:$C$286,$A10,Denetimler!$D$2:$D$286,"RSA",Denetimler!$E$2:$E$286,"İç denetim"),"") -> 92.490842 | I10: =IFERROR(AVERAGEIFS(Denetimler!$L$2:$L$286,Denetimler!$C$2:$C$286,$A10,Denetimler!$D$2:$D$286,"RSA",Denetimler!$E$2:$E$286,"Esas denetim"),"") -> 98.351648 | J10: =IF(OR(H10="",I10=""),"",H10-I10) -> -5.8608059 | K10: =IFERROR(AVERAGE(C10,F10,I10),"") -> 83.617216 | L10: =IFERROR(RANK(K10,$K$5:$K$12),"") -> 7 | M10: =COUNTIF(Bulgular!$H$2:$H$570,A10) -> 44 | N10: =COUNTIFS(Bulgular!$H$2:$H$570,A10,Bulgular!$F$2:$F$570,"Kritik") -> 8 | O10: =COUNTIFS(DOF_Takip!$C$2:$C$200,A10,DOF_Takip!$J$2:$J$200,"Açık")+COUNTIFS(DOF_Takip!$C$2:$C$200,A10,DOF_Takip!$J$2:$J$200,"Gecikmiş") -> 1 | P10: =COUNTIFS(DOF_Takip!$C$2:$C$200,A10,DOF_Takip!$J$2:$J$200,"Gecikmiş") -> 1
A11: =Magazalar!A8 -> Mağaza G | B11: =IFERROR(AVERAGEIFS(Denetimler!$L$2:$L$286,Denetimler!$C$2:$C$286,$A11,Denetimler!$D$2:$D$286,"ASA",Denetimler!$E$2:$E$286,"İç denetim"),"") -> 81.25 | C11: =IFERROR(AVERAGEIFS(Denetimler!$L$2:$L$286,Denetimler!$C$2:$C$286,$A11,Denetimler!$D$2:$D$286,"ASA",Denetimler!$E$2:$E$286,"Esas denetim"),"") -> 92.5 | D11: =IF(OR(B11="",C11=""),"",B11-C11) -> -11.25 | E11: =IFERROR(AVERAGEIFS(Denetimler!$L$2:$L$286,Denetimler!$C$2:$C$286,$A11,Denetimler!$D$2:$D$286,"PAP",Denetimler!$E$2:$E$286,"İç denetim"),"") -> 73.888889 | F11: =IFERROR(AVERAGEIFS(Denetimler!$L$2:$L$286,Denetimler!$C$2:$C$286,$A11,Denetimler!$D$2:$D$286,"PAP",Denetimler!$E$2:$E$286,"Esas denetim"),"") -> 65 | G11: =IF(OR(E11="",F11=""),"",E11-F11) -> 8.8888889 | H11: =IFERROR(AVERAGEIFS(Denetimler!$L$2:$L$286,Denetimler!$C$2:$C$286,$A11,Denetimler!$D$2:$D$286,"RSA",Denetimler!$E$2:$E$286,"İç denetim"),"") -> 95.054945 | I11: =IFERROR(AVERAGEIFS(Denetimler!$L$2:$L$286,Denetimler!$C$2:$C$286,$A11,Denetimler!$D$2:$D$286,"RSA",Denetimler!$E$2:$E$286,"Esas denetim"),"") -> 92.857143 | J11: =IF(OR(H11="",I11=""),"",H11-I11) -> 2.1978022 | K11: =IFERROR(AVERAGE(C11,F11,I11),"") -> 83.452381 | L11: =IFERROR(RANK(K11,$K$5:$K$12),"") -> 8 | M11: =COUNTIF(Bulgular!$H$2:$H$570,A11) -> 44 | N11: =COUNTIFS(Bulgular!$H$2:$H$570,A11,Bulgular!$F$2:$F$570,"Kritik") -> 11 | O11: =COUNTIFS(DOF_Takip!$C$2:$C$200,A11,DOF_Takip!$J$2:$J$200,"Açık")+COUNTIFS(DOF_Takip!$C$2:$C$200,A11,DOF_Takip!$J$2:$J$200,"Gecikmiş") -> 1 | P11: =COUNTIFS(DOF_Takip!$C$2:$C$200,A11,DOF_Takip!$J$2:$J$200,"Gecikmiş") -> 1
A12: =Magazalar!A9 -> Mağaza H | B12: =IFERROR(AVERAGEIFS(Denetimler!$L$2:$L$286,Denetimler!$C$2:$C$286,$A12,Denetimler!$D$2:$D$286,"ASA",Denetimler!$E$2:$E$286,"İç denetim"),"") -> 83.75 | C12: =IFERROR(AVERAGEIFS(Denetimler!$L$2:$L$286,Denetimler!$C$2:$C$286,$A12,Denetimler!$D$2:$D$286,"ASA",Denetimler!$E$2:$E$286,"Esas denetim"),"") -> 82.5 | D12: =IF(OR(B12="",C12=""),"",B12-C12) -> 1.25 | E12: =IFERROR(AVERAGEIFS(Denetimler!$L$2:$L$286,Denetimler!$C$2:$C$286,$A12,Denetimler!$D$2:$D$286,"PAP",Denetimler!$E$2:$E$286,"İç denetim"),"") -> 80 | F12: =IFERROR(AVERAGEIFS(Denetimler!$L$2:$L$286,Denetimler!$C$2:$C$286,$A12,Denetimler!$D$2:$D$286,"PAP",Denetimler!$E$2:$E$286,"Esas denetim"),"") -> 78.333333 | G12: =IF(OR(E12="",F12=""),"",E12-F12) -> 1.6666667 | H12: =IFERROR(AVERAGEIFS(Denetimler!$L$2:$L$286,Denetimler!$C$2:$C$286,$A12,Denetimler!$D$2:$D$286,"RSA",Denetimler!$E$2:$E$286,"İç denetim"),"") -> 94.688645 | I12: =IFERROR(AVERAGEIFS(Denetimler!$L$2:$L$286,Denetimler!$C$2:$C$286,$A12,Denetimler!$D$2:$D$286,"RSA",Denetimler!$E$2:$E$286,"Esas denetim"),"") -> 92.857143 | J12: =IF(OR(H12="",I12=""),"",H12-I12) -> 1.8315018 | K12: =IFERROR(AVERAGE(C12,F12,I12),"") -> 84.563492 | L12: =IFERROR(RANK(K12,$K$5:$K$12),"") -> 5 | M12: =COUNTIF(Bulgular!$H$2:$H$570,A12) -> 40 | N12: =COUNTIFS(Bulgular!$H$2:$H$570,A12,Bulgular!$F$2:$F$570,"Kritik") -> 8 | O12: =COUNTIFS(DOF_Takip!$C$2:$C$200,A12,DOF_Takip!$J$2:$J$200,"Açık")+COUNTIFS(DOF_Takip!$C$2:$C$200,A12,DOF_Takip!$J$2:$J$200,"Gecikmiş") -> 0 | P12: =COUNTIFS(DOF_Takip!$C$2:$C$200,A12,DOF_Takip!$J$2:$J$200,"Gecikmiş") -> 0
A13: BÖLGE | B13: =IFERROR(AVERAGE(B5:B12),"") -> 89.088542 | C13: =IFERROR(AVERAGE(C5:C12),"") -> 88.28125 | D13: =IFERROR(AVERAGE(D5:D12),"") -> 0.80729167 | E13: =IFERROR(AVERAGE(E5:E12),"") -> 84.444444 | F13: =IFERROR(AVERAGE(F5:F12),"") -> 80.833333 | G13: =IFERROR(AVERAGE(G5:G12),"") -> 3.6111111 | H13: =IFERROR(AVERAGE(H5:H12),"") -> 94.288004 | I13: =IFERROR(AVERAGE(I5:I12),"") -> 94.848901 | ... K13: =IFERROR(AVERAGE(K5:K12),"") -> 87.987828 | M13: =SUM(M5:M12) -> 269 | N13: =SUM(N5:N12) -> 52 | O13: =SUM(O5:O12) -> 7 | P13: =SUM(P5:P12) -> 7
A15: Takvim durumu
A16: Yapılan iç denetim | C16: =COUNTIF(Denetim_Takvimi!$G:$G,"Yapıldı") -> 61
A17: Geciken iç denetim | C17: =COUNTIF(Denetim_Takvimi!$G:$G,"Gecikti") -> 11
A18: 30 gün içinde iç denetim | C18: =COUNTIF(Denetim_Takvimi!$G:$G,"Yaklaşıyor") -> 12
A19: 30 gün içinde esas denetim | C19: =COUNTIF(Denetim_Takvimi!$N:$N,"Yaklaşıyor") -> 5
A20: Rotasyon uyarısı | C20: =COUNTA(Denetim_Takvimi!$H$5:$H$100)-COUNTIF(Denetim_Takvimi!$H$5:$H$100,"Uygun*") -> 1

Sheet Oncelik_Listesi
A1: En Sık Tekrar Eden Uygunsuzluklar — Eğitim Önceliği
A2: Filtre: | B2: Tümü | C2: Tümü / ASA / PAP / RSA
A3: Ağırlıklı skor = bulgu sayısı × önem katsayısı (kritik 2, major 1,5, minör 1). Liste skora göre büyükten küçüğe sıralanır.
A5: Sıra | B5: Madde Kodu | C5: Madde | D5: Tür | E5: Önem | F5: Bulgu (iç) | G5: Bulgu (esas) | H5: Ağırlıklı Skor | I5: Eğitim Konusu | J5: En Sık Görüldüğü Mağaza | L5: Satır | N5: Kod | O5: Bulgu (iç) | P5: Bulgu (esas) | Q5: Toplam | R5: Ağırlıklı Skor | S5: Sıralama Anahtarı
A6: =IF(L6="","",1) -> 1 | B6: =IF(L6="","",INDEX(Madde_Listesi!$B$2:$B$24,L6)) -> P-1.1 | C6: =IF(L6="","",INDEX(Madde_Listesi!$C$2:$C$24,L6)) -> Kasa farkları kayıt altına alınmış ve açıklanmış | D6: =IF(L6="","",INDEX(Madde_Listesi!$A$2:$A$24,L6)) -> PAP | E6: =IF(L6="","",INDEX(Madde_Listesi!$E$2:$E$24,L6)) -> Kritik | F6: =IF(L6="","",INDEX($O$6:$O$28,L6)) -> 21 | G6: =IF(L6="","",INDEX($P$6:$P$28,L6)) -> 7 | H6: =IF(L6="","",INDEX($R$6:$R$28,L6)) -> 56 | I6: =IF(L6="","",INDEX(Madde_Listesi!$F$2:$F$24,L6)) -> Kasa prosedürleri | J6: =IF(L6="","",INDEX(Madde_Magaza!$B$1:$I$1,MATCH(MAX(INDEX(Madde_Magaza!$B$2:$I$24,L6,0)),INDEX(Madde_Magaza!$B$2:$I$24,L6,0),0))) -> Mağaza G | L6: =IFERROR(MATCH(LARGE($S$6:$S$28,1),$S$6:$S$28,0),"") -> 17 | N6: =Madde_Listesi!B2 -> R-1.2 | O6: =COUNTIFS(Bulgular!$B$2:$B$570,N6,Bulgular!$J$2:$J$570,"İç denetim") -> 8 | P6: =COUNTIFS(Bulgular!$B$2:$B$570,N6,Bulgular!$J$2:$J$570,"Esas denetim") -> 3 | Q6: =O6+P6 -> 11 | R6: =Q6*INDEX(Ayarlar!$B$6:$B$8,MATCH(Madde_Listesi!E2,Ayarlar!$A$6:$A$8,0)) -> 16.5 | S6: =IF(OR($B$2="Tümü",Madde_Listesi!A2=$B$2),IF(Q6>0,R6+ROW()/10000,""),"") -> 16.5006
A7: =IF(L7="","",2) -> 2 | B7: =IF(L7="","",INDEX(Madde_Listesi!$B$2:$B$24,L7)) -> A-3.2 | C7: =IF(L7="","",INDEX(Madde_Listesi!$C$2:$C$24,L7)) -> Stok sayımı ve sipariş kayıtları tutarlı | D7: =IF(L7="","",INDEX(Madde_Listesi!$A$2:$A$24,L7)) -> ASA | E7: =IF(L7="","",INDEX(Madde_Listesi!$E$2:$E$24,L7)) -> Major | F7: =IF(L7="","",INDEX($O$6:$O$28,L7)) -> 19 | G7: =IF(L7="","",INDEX($P$6:$P$28,L7)) -> 11 | H7: =IF(L7="","",INDEX($R$6:$R$28,L7)) -> 45 | I7: =IF(L7="","",INDEX(Madde_Listesi!$F$2:$F$24,L7)) -> Stok ve sipariş yönetimi | J7: =IF(L7="","",INDEX(Madde_Magaza!$B$1:$I$1,MATCH(MAX(INDEX(Madde_Magaza!$B$2:$I$24,L7,0)),INDEX(Madde_Magaza!$B$2:$I$24,L7,0),0))) -> Mağaza H | L7: =IFERROR(MATCH(LARGE($S$6:$S$28,2),$S$6:$S$28,0),"") -> 15 | N7: =Madde_Listesi!B3 -> R-2.1 | O7: =COUNTIFS(Bulgular!$B$2:$B$570,N7,Bulgular!$J$2:$J$570,"İç denetim") -> 4 | P7: =COUNTIFS(Bulgular!$B$2:$B$570,N7,Bulgular!$J$2:$J$570,"Esas denetim") -> 2 | Q7: =O7+P7 -> 6 | R7: =Q7*INDEX(Ayarlar!$B$6:$B$8,MATCH(Madde_Listesi!E3,Ayarlar!$A$6:$A$8,0)) -> 12 | S7: =IF(OR($B$2="Tümü",Madde_Listesi!A3=$B$2),IF(Q7>0,R7+ROW()/10000,""),"") -> 12.0007
A8: =IF(L8="","",3) -> 3 | B8: =IF(L8="","",INDEX(Madde_Listesi!$B$2:$B$24,L8)) -> R-2.2 | C8: =IF(L8="","",INDEX(Madde_Listesi!$C$2:$C$24,L8)) -> Sıcaklık kayıtları tam ve zamanında tutulmuş | D8: =IF(L8="","",INDEX(Madde_Listesi!$A$2:$A$24,L8)) -> RSA | E8: =IF(L8="","",INDEX(Madde_Listesi!$E$2:$E$24,L8)) -> Major | F8: =IF(L8="","",INDEX($O$6:$O$28,L8)) -> 23 | G8: =IF(L8="","",INDEX($P$6:$P$28,L8)) -> 7 | H8: =IF(L8="","",INDEX($R$6:$R$28,L8)) -> 45 | I8: =IF(L8="","",INDEX(Madde_Listesi!$F$2:$F$24,L8)) -> Soğuk zincir ve sıcaklık kontrolü | J8: =IF(L8="","",INDEX(Madde_Magaza!$B$1:$I$1,MATCH(MAX(INDEX(Madde_Magaza!$B$2:$I$24,L8,0)),INDEX(Madde_Magaza!$B$2:$I$24,L8,0),0))) -> Mağaza F | L8: =IFERROR(MATCH(LARGE($S$6:$S$28,3),$S$6:$S$28,0),"") -> 3 | N8: =Madde_Listesi!B4 -> R-2.2 | O8: =COUNTIFS(Bulgular!$B$2:$B$570,N8,Bulgular!$J$2:$J$570,"İç denetim") -> 23 | P8: =COUNTIFS(Bulgular!$B$2:$B$570,N8,Bulgular!$J$2:$J$570,"Esas denetim") -> 7 | Q8: =O8+P8 -> 30 | R8: =Q8*INDEX(Ayarlar!$B$6:$B$8,MATCH(Madde_Listesi!E4,Ayarlar!$A$6:$A$8,0)) -> 45 | S8: =IF(OR($B$2="Tümü",Madde_Listesi!A4=$B$2),IF(Q8>0,R8+ROW()/10000,""),"") -> 45.0008
A9: =IF(L9="","",4) -> 4 | B9: =IF(L9="","",INDEX(Madde_Listesi!$B$2:$B$24,L9)) -> R-4.3 | C9: =IF(L9="","",INDEX(Madde_Listesi!$C$2:$C$24,L9)) -> Kimyasallar etiketli ve gıdadan ayrı saklanıyor | D9: =IF(L9="","",INDEX(Madde_Listesi!$A$2:$A$24,L9)) -> RSA | E9: =IF(L9="","",INDEX(Madde_Listesi!$E$2:$E$24,L9)) -> Major | F9: =IF(L9="","",INDEX($O$6:$O$28,L9)) -> 16 | G9: =IF(L9="","",INDEX($P$6:$P$28,L9)) -> 2 | H9: =IF(L9="","",INDEX($R$6:$R$28,L9)) -> 27 | I9: =IF(L9="","",INDEX(Madde_Listesi!$F$2:$F$24,L9)) -> Kimyasal güvenliği | J9: =IF(L9="","",INDEX(Madde_Magaza!$B$1:$I$1,MATCH(MAX(INDEX(Madde_Magaza!$B$2:$I$24,L9,0)),INDEX(Madde_Magaza!$B$2:$I$24,L9,0),0))) -> Mağaza C | L9: =IFERROR(MATCH(LARGE($S$6:$S$28,4),$S$6:$S$28,0),"") -> 8 | N9: =Madde_Listesi!B5 -> R-3.1 | O9: =COUNTIFS(Bulgular!$B$2:$B$570,N9,Bulgular!$J$2:$J$570,"İç denetim") -> 4 | P9: =COUNTIFS(Bulgular!$B$2:$B$570,N9,Bulgular!$J$2:$J$570,"Esas denetim") -> 0 | Q9: =O9+P9 -> 4 | R9: =Q9*INDEX(Ayarlar!$B$6:$B$8,MATCH(Madde_Listesi!E5,Ayarlar!$A$6:$A$8,0)) -> 6 | S9: =IF(OR($B$2="Tümü",Madde_Listesi!A5=$B$2),IF(Q9>0,R9+ROW()/10000,""),"") -> 6.0009
A10: =IF(L10="","",5) -> 5 | B10: =IF(L10="","",INDEX(Madde_Listesi!$B$2:$B$24,L10)) -> A-1.1 | C10: =IF(L10="","",INDEX(Madde_Listesi!$C$2:$C$24,L10)) -> Vardiya planı yoğunluğa uygun hazırlanmış | D10: =IF(L10="","",INDEX(Madde_Listesi!$A$2:$A$24,L10)) -> ASA | E10: =IF(L10="","",INDEX(Madde_Listesi!$E$2:$E$24,L10)) -> Major | F10: =IF(L10="","",INDEX($O$6:$O$28,L10)) -> 12 | G10: =IF(L10="","",INDEX($P$6:$P$28,L10)) -> 4 | H10: =IF(L10="","",INDEX($R$6:$R$28,L10)) -> 24 | I10: =IF(L10="","",INDEX(Madde_Listesi!$F$2:$F$24,L10)) -> Vardiya planlama | J10: =IF(L10="","",INDEX(Madde_Magaza!$B$1:$I$1,MATCH(MAX(INDEX(Madde_Magaza!$B$2:$I$24,L10,0)),INDEX(Madde_Magaza!$B$2:$I$24,L10,0),0))) -> Mağaza G | L10: =IFERROR(MATCH(LARGE($S$6:$S$28,5),$S$6:$S$28,0),"") -> 10 | N10: =Madde_Listesi!B6 -> R-3.2 | O10: =COUNTIFS(Bulgular!$B$2:$B$570,N10,Bulgular!$J$2:$J$570,"İç denetim") -> 1 | P10: =COUNTIFS(Bulgular!$B$2:$B$570,N10,Bulgular!$J$2:$J$570,"Esas denetim") -> 2 | Q10: =O10+P10 -> 3 | R10: =Q10*INDEX(Ayarlar!$B$6:$B$8,MATCH(Madde_Listesi!E6,Ayarlar!$A$6:$A$8,0)) -> 3 | S10: =IF(OR($B$2="Tümü",Madde_Listesi!A6=$B$2),IF(Q10>0,R10+ROW()/10000,""),"") -> 3.001
A11: =IF(L11="","",6) -> 6 | B11: =IF(L11="","",INDEX(Madde_Listesi!$B$2:$B$24,L11)) -> R-4.1 | C11: =IF(L11="","",INDEX(Madde_Listesi!$C$2:$C$24,L11)) -> Ürünlerin son kullanma tarihleri geçerli ve etiketli | D11: =IF(L11="","",INDEX(Madde_Listesi!$A$2:$A$24,L11)) -> RSA | E11: =IF(L11="","",INDEX(Madde_Listesi!$E$2:$E$24,L11)) -> Kritik | F11: =IF(L11="","",INDEX($O$6:$O$28,L11)) -> 6 | G11: =IF(L11="","",INDEX($P$6:$P$28,L11)) -> 6 | H11: =IF(L11="","",INDEX($R$6:$R$28,L11)) -> 24 | I11: =IF(L11="","",INDEX(Madde_Listesi!$F$2:$F$24,L11)) -> Ürün tarihleme ve etiketleme | J11: =IF(L11="","",INDEX(Madde_Magaza!$B$1:$I$1,MATCH(MAX(INDEX(Madde_Magaza!$B$2:$I$24,L11,0)),INDEX(Madde_Magaza!$B$2:$I$24,L11,0),0))) -> Mağaza A | L11: =IFERROR(MATCH(LARGE($S$6:$S$28,6),$S$6:$S$28,0),"") -> 6 | N11: =Madde_Listesi!B7 -> R-4.1 | O11: =COUNTIFS(Bulgular!$B$2:$B$570,N11,Bulgular!$J$2:$J$570,"İç denetim") -> 6 | P11: =COUNTIFS(Bulgular!$B$2:$B$570,N11,Bulgular!$J$2:$J$570,"Esas denetim") -> 6 | Q11: =O11+P11 -> 12 | R11: =Q11*INDEX(Ayarlar!$B$6:$B$8,MATCH(Madde_Listesi!E7,Ayarlar!$A$6:$A$8,0)) -> 24 | S11: =IF(OR($B$2="Tümü",Madde_Listesi!A7=$B$2),IF(Q11>0,R11+ROW()/10000,""),"") -> 24.0011
A12: =IF(L12="","",7) -> 7 | B12: =IF(L12="","",INDEX(Madde_Listesi!$B$2:$B$24,L12)) -> P-3.1 | C12: =IF(L12="","",INDEX(Madde_Listesi!$C$2:$C$24,L12)) -> Depo ve kasa anahtarları yetkili kişide | D12: =IF(L12="","",INDEX(Madde_Listesi!$A$2:$A$24,L12)) -> PAP | E12: =IF(L12="","",INDEX(Madde_Listesi!$E$2:$E$24,L12)) -> Major | F12: =IF(L12="","",INDEX($O$6:$O$28,L12)) -> 12 | G12: =IF(L12="","",INDEX($P$6:$P$28,L12)) -> 3 | H12: =IF(L12="","",INDEX($R$6:$R$28,L12)) -> 22.5 | I12: =IF(L12="","",INDEX(Madde_Listesi!$F$2:$F$24,L12)) -> Mağaza güvenliği | J12: =IF(L12="","",INDEX(Madde_Magaza!$B$1:$I$1,MATCH(MAX(INDEX(Madde_Magaza!$B$2:$I$24,L12,0)),INDEX(Madde_Magaza!$B$2:$I$24,L12,0),0))) -> Mağaza D | L12: =IFERROR(MATCH(LARGE($S$6:$S$28,7),$S$6:$S$28,0),"") -> 21 | N12: =Madde_Listesi!B8 -> R-4.2 | O12: =COUNTIFS(Bulgular!$B$2:$B$570,N12,Bulgular!$J$2:$J$570,"İç denetim") -> 4 | P12: =COUNTIFS(Bulgular!$B$2:$B$570,N12,Bulgular!$J$2:$J$570,"Esas denetim") -> 1 | Q12: =O12+P12 -> 5 | R12: =Q12*INDEX(Ayarlar!$B$6:$B$8,MATCH(Madde_Listesi!E8,Ayarlar!$A$6:$A$8,0)) -> 7.5 | S12: =IF(OR($B$2="Tümü",Madde_Listesi!A8=$B$2),IF(Q12>0,R12+ROW()/10000,""),"") -> 7.5012
A13: =IF(L13="","",8) -> 8 | B13: =IF(L13="","",INDEX(Madde_Listesi!$B$2:$B$24,L13)) -> P-2.1 | C13: =IF(L13="","",INDEX(Madde_Listesi!$C$2:$C$24,L13)) -> İptal ve iade işlemleri yönetici onaylı | D13: =IF(L13="","",INDEX(Madde_Listesi!$A$2:$A$24,L13)) -> PAP | E13: =IF(L13="","",INDEX(Madde_Listesi!$E$2:$E$24,L13)) -> Major | F13: =IF(L13="","",INDEX($O$6:$O$28,L13)) -> 9 | G13: =IF(L13="","",INDEX($P$6:$P$28,L13)) -> 6 | H13: =IF(L13="","",INDEX($R$6:$R$28,L13)) -> 22.5 | I13: =IF(L13="","",INDEX(Madde_Listesi!$F$2:$F$24,L13)) -> İptal ve iade süreçleri | J13: =IF(L13="","",INDEX(Madde_Magaza!$B$1:$I$1,MATCH(MAX(INDEX(Madde_Magaza!$B$2:$I$24,L13,0)),INDEX(Madde_Magaza!$B$2:$I$24,L13,0),0))) -> Mağaza D | L13: =IFERROR(MATCH(LARGE($S$6:$S$28,8),$S$6:$S$28,0),"") -> 19 | N13: =Madde_Listesi!B9 -> R-4.3 | O13: =COUNTIFS(Bulgular!$B$2:$B$570,N13,Bulgular!$J$2:$J$570,"İç denetim") -> 16 | P13: =COUNTIFS(Bulgular!$B$2:$B$570,N13,Bulgular!$J$2:$J$570,"Esas denetim") -> 2 | Q13: =O13+P13 -> 18 | R13: =Q13*INDEX(Ayarlar!$B$6:$B$8,MATCH(Madde_Listesi!E9,Ayarlar!$A$6:$A$8,0)) -> 27 | S13: =IF(OR($B$2="Tümü",Madde_Listesi!A9=$B$2),IF(Q13>0,R13+ROW()/10000,""),"") -> 27.0013
A14: =IF(L14="","",9) -> 9 | B14: =IF(L14="","",INDEX(Madde_Listesi!$B$2:$B$24,L14)) -> R-1.2 | C14: =IF(L14="","",INDEX(Madde_Listesi!$C$2:$C$24,L14)) -> Çalışan takı ve kişisel hijyen kurallarına uyuyor | D14: =IF(L14="","",INDEX(Madde_Listesi!$A$2:$A$24,L14)) -> RSA | E14: =IF(L14="","",INDEX(Madde_Listesi!$E$2:$E$24,L14)) -> Major | F14: =IF(L14="","",INDEX($O$6:$O$28,L14)) -> 8 | G14: =IF(L14="","",INDEX($P$6:$P$28,L14)) -> 3 | H14: =IF(L14="","",INDEX($R$6:$R$28,L14)) -> 16.5 | I14: =IF(L14="","",INDEX(Madde_Listesi!$F$2:$F$24,L14)) -> Kişisel hijyen | J14: =IF(L14="","",INDEX(Madde_Magaza!$B$1:$I$1,MATCH(MAX(INDEX(Madde_Magaza!$B$2:$I$24,L14,0)),INDEX(Madde_Magaza!$B$2:$I$24,L14,0),0))) -> Mağaza D | L14: =IFERROR(MATCH(LARGE($S$6:$S$28,9),$S$6:$S$28,0),"") -> 1 | N14: =Madde_Listesi!B10 -> R-4.4 | O14: =COUNTIFS(Bulgular!$B$2:$B$570,N14,Bulgular!$J$2:$J$570,"İç denetim") -> 2 | P14: =COUNTIFS(Bulgular!$B$2:$B$570,N14,Bulgular!$J$2:$J$570,"Esas denetim") -> 0 | Q14: =O14+P14 -> 2 | R14: =Q14*INDEX(Ayarlar!$B$6:$B$8,MATCH(Madde_Listesi!E10,Ayarlar!$A$6:$A$8,0)) -> 2 | S14: =IF(OR($B$2="Tümü",Madde_Listesi!A10=$B$2),IF(Q14>0,R14+ROW()/10000,""),"") -> 2.0014
A15: =IF(L15="","",10) -> 10 | B15: =IF(L15="","",INDEX(Madde_Listesi!$B$2:$B$24,L15)) -> P-3.2 | C15: =IF(L15="","",INDEX(Madde_Listesi!$C$2:$C$24,L15)) -> Kamera kayıtları erişilebilir ve süresi uygun | D15: =IF(L15="","",INDEX(Madde_Listesi!$A$2:$A$24,L15)) -> PAP | E15: =IF(L15="","",INDEX(Madde_Listesi!$E$2:$E$24,L15)) -> Minör | F15: =IF(L15="","",INDEX($O$6:$O$28,L15)) -> 10 | G15: =IF(L15="","",INDEX($P$6:$P$28,L15)) -> 5 | H15: =IF(L15="","",INDEX($R$6:$R$28,L15)) -> 15 | I15: =IF(L15="","",INDEX(Madde_Listesi!$F$2:$F$24,L15)) -> Mağaza güvenliği | J15: =IF(L15="","",INDEX(Madde_Magaza!$B$1:$I$1,MATCH(MAX(INDEX(Madde_Magaza!$B$2:$I$24,L15,0)),INDEX(Madde_Magaza!$B$2:$I$24,L15,0),0))) -> Mağaza D | L15: =IFERROR(MATCH(LARGE($S$6:$S$28,10),$S$6:$S$28,0),"") -> 22 | N15: =Madde_Listesi!B11 -> A-1.1 | O15: =COUNTIFS(Bulgular!$B$2:$B$570,N15,Bulgular!$J$2:$J$570,"İç denetim") -> 12 | P15: =COUNTIFS(Bulgular!$B$2:$B$570,N15,Bulgular!$J$2:$J$570,"Esas denetim") -> 4 | Q15: =O15+P15 -> 16 | R15: =Q15*INDEX(Ayarlar!$B$6:$B$8,MATCH(Madde_Listesi!E11,Ayarlar!$A$6:$A$8,0)) -> 24 | S15: =IF(OR($B$2="Tümü",Madde_Listesi!A11=$B$2),IF(Q15>0,R15+ROW()/10000,""),"") -> 24.0015
A16: =IF(L16="","",11) -> 11 | B16: =IF(L16="","",INDEX(Madde_Listesi!$B$2:$B$24,L16)) -> A-4.1 | C16: =IF(L16="","",INDEX(Madde_Listesi!$C$2:$C$24,L16)) -> Zorunlu eğitimler tamamlanmış | D16: =IF(L16="","",INDEX(Madde_Listesi!$A$2:$A$24,L16)) -> ASA | E16: =IF(L16="","",INDEX(Madde_Listesi!$E$2:$E$24,L16)) -> Major | F16: =IF(L16="","",INDEX($O$6:$O$28,L16)) -> 5 | G16: =IF(L16="","",INDEX($P$6:$P$28,L16)) -> 5 | H16: =IF(L16="","",INDEX($R$6:$R$28,L16)) -> 15 | I16: =IF(L16="","",INDEX(Madde_Listesi!$F$2:$F$24,L16)) -> Eğitim takibi | J16: =IF(L16="","",INDEX(Madde_Magaza!$B$1:$I$1,MATCH(MAX(INDEX(Madde_Magaza!$B$2:$I$24,L16,0)),INDEX(Madde_Magaza!$B$2:$I$24,L16,0),0))) -> Mağaza F | L16: =IFERROR(MATCH(LARGE($S$6:$S$28,11),$S$6:$S$28,0),"") -> 16 | N16: =Madde_Listesi!B12 -> A-1.2 | O16: =COUNTIFS(Bulgular!$B$2:$B$570,N16,Bulgular!$J$2:$J$570,"İç denetim") -> 4 | P16: =COUNTIFS(Bulgular!$B$2:$B$570,N16,Bulgular!$J$2:$J$570,"Esas denetim") -> 2 | Q16: =O16+P16 -> 6 | R16: =Q16*INDEX(Ayarlar!$B$6:$B$8,MATCH(Madde_Listesi!E12,Ayarlar!$A$6:$A$8,0)) -> 12 | S16: =IF(OR($B$2="Tümü",Madde_Listesi!A12=$B$2),IF(Q16>0,R16+ROW()/10000,""),"") -> 12.0016
A17: =IF(L17="","",12) -> 12 | B17: =IF(L17="","",INDEX(Madde_Listesi!$B$2:$B$24,L17)) -> P-4.1 | C17: =IF(L17="","",INDEX(Madde_Listesi!$C$2:$C$24,L17)) -> Fire ve zayi kayıtları belgeli | D17: =IF(L17="","",INDEX(Madde_Listesi!$A$2:$A$24,L17)) -> PAP | E17: =IF(L17="","",INDEX(Madde_Listesi!$E$2:$E$24,L17)) -> Major | F17: =IF(L17="","",INDEX($O$6:$O$28,L17)) -> 7 | G17: =IF(L17="","",INDEX($P$6:$P$28,L17)) -> 2 | H17: =IF(L17="","",INDEX($R$6:$R$28,L17)) -> 13.5 | I17: =IF(L17="","",INDEX(Madde_Listesi!$F$2:$F$24,L17)) -> Stok ve sipariş yönetimi | J17: =IF(L17="","",INDEX(Madde_Magaza!$B$1:$I$1,MATCH(MAX(INDEX(Madde_Magaza!$B$2:$I$24,L17,0)),INDEX(Madde_Magaza!$B$2:$I$24,L17,0),0))) -> Mağaza D | L17: =IFERROR(MATCH(LARGE($S$6:$S$28,12),$S$6:$S$28,0),"") -> 23 | N17: =Madde_Listesi!B13 -> A-2.1 | O17: =COUNTIFS(Bulgular!$B$2:$B$570,N17,Bulgular!$J$2:$J$570,"İç denetim") -> 7 | P17: =COUNTIFS(Bulgular!$B$2:$B$570,N17,Bulgular!$J$2:$J$570,"Esas denetim") -> 1 | Q17: =O17+P17 -> 8 | R17: =Q17*INDEX(Ayarlar!$B$6:$B$8,MATCH(Madde_Listesi!E13,Ayarlar!$A$6:$A$8,0)) -> 8 | S17: =IF(OR($B$2="Tümü",Madde_Listesi!A13=$B$2),IF(Q17>0,R17+ROW()/10000,""),"") -> 8.0017
A18: =IF(L18="","",13) -> 13 | B18: =IF(L18="","",INDEX(Madde_Listesi!$B$2:$B$24,L18)) -> A-1.2 | C18: =IF(L18="","",INDEX(Madde_Listesi!$C$2:$C$24,L18)) -> Kasa açılış-kapanış prosedürü uygulanıyor | D18: =IF(L18="","",INDEX(Madde_Listesi!$A$2:$A$24,L18)) -> ASA | E18: =IF(L18="","",INDEX(Madde_Listesi!$E$2:$E$24,L18)) -> Kritik | F18: =IF(L18="","",INDEX($O$6:$O$28,L18)) -> 4 | G18: =IF(L18="","",INDEX($P$6:$P$28,L18)) -> 2 | H18: =IF(L18="","",INDEX($R$6:$R$28,L18)) -> 12 | I18: =IF(L18="","",INDEX(Madde_Listesi!$F$2:$F$24,L18)) -> Kasa prosedürleri | J18: =IF(L18="","",INDEX(Madde_Magaza!$B$1:$I$1,MATCH(MAX(INDEX(Madde_Magaza!$B$2:$I$24,L18,0)),INDEX(Madde_Magaza!$B$2:$I$24,L18,0),0))) -> Mağaza B | L18: =IFERROR(MATCH(LARGE($S$6:$S$28,13),$S$6:$S$28,0),"") -> 11 | N18: =Madde_Listesi!B14 -> A-2.2 | O18: =COUNTIFS(Bulgular!$B$2:$B$570,N18,Bulgular!$J$2:$J$570,"İç denetim") -> 1 | P18: =COUNTIFS(Bulgular!$B$2:$B$570,N18,Bulgular!$J$2:$J$570,"Esas denetim") -> 1 | Q18: =O18+P18 -> 2 | R18: =Q18*INDEX(Ayarlar!$B$6:$B$8,MATCH(Madde_Listesi!E14,Ayarlar!$A$6:$A$8,0)) -> 3 | S18: =IF(OR($B$2="Tümü",Madde_Listesi!A14=$B$2),IF(Q18>0,R18+ROW()/10000,""),"") -> 3.0018
A19: =IF(L19="","",14) -> 14 | B19: =IF(L19="","",INDEX(Madde_Listesi!$B$2:$B$24,L19)) -> R-2.1 | C19: =IF(L19="","",INDEX(Madde_Listesi!$C$2:$C$24,L19)) -> Soğutucular uygun sıcaklıkta | D19: =IF(L19="","",INDEX(Madde_Listesi!$A$2:$A$24,L19)) -> RSA | E19: =IF(L19="","",INDEX(Madde_Listesi!$E$2:$E$24,L19)) -> Kritik | F19: =IF(L19="","",INDEX($O$6:$O$28,L19)) -> 4 | G19: =IF(L19="","",INDEX($P$6:$P$28,L19)) -> 2 | H19: =IF(L19="","",INDEX($R$6:$R$28,L19)) -> 12 | I19: =IF(L19="","",INDEX(Madde_Listesi!$F$2:$F$24,L19)) -> Soğuk zincir ve sıcaklık kontrolü | J19: =IF(L19="","",INDEX(Madde_Magaza!$B$1:$I$1,MATCH(MAX(INDEX(Madde_Magaza!$B$2:$I$24,L19,0)),INDEX(Madde_Magaza!$B$2:$I$24,L19,0),0))) -> Mağaza A | L19: =IFERROR(MATCH(LARGE($S$6:$S$28,14),$S$6:$S$28,0),"") -> 2 | N19: =Madde_Listesi!B15 -> A-3.1 | O19: =COUNTIFS(Bulgular!$B$2:$B$570,N19,Bulgular!$J$2:$J$570,"İç denetim") -> 7 | P19: =COUNTIFS(Bulgular!$B$2:$B$570,N19,Bulgular!$J$2:$J$570,"Esas denetim") -> 1 | Q19: =O19+P19 -> 8 | R19: =Q19*INDEX(Ayarlar!$B$6:$B$8,MATCH(Madde_Listesi!E15,Ayarlar!$A$6:$A$8,0)) -> 8 | S19: =IF(OR($B$2="Tümü",Madde_Listesi!A15=$B$2),IF(Q19>0,R19+ROW()/10000,""),"") -> 8.0019
A20: =IF(L20="","",15) -> 15 | B20: =IF(L20="","",INDEX(Madde_Listesi!$B$2:$B$24,L20)) -> P-2.2 | C20: =IF(L20="","",INDEX(Madde_Listesi!$C$2:$C$24,L20)) -> Personel indirimleri kurala uygun kullanılıyor | D20: =IF(L20="","",INDEX(Madde_Listesi!$A$2:$A$24,L20)) -> PAP | E20: =IF(L20="","",INDEX(Madde_Listesi!$E$2:$E$24,L20)) -> Minör | F20: =IF(L20="","",INDEX($O$6:$O$28,L20)) -> 5 | G20: =IF(L20="","",INDEX($P$6:$P$28,L20)) -> 6 | H20: =IF(L20="","",INDEX($R$6:$R$28,L20)) -> 11 | I20: =IF(L20="","",INDEX(Madde_Listesi!$F$2:$F$24,L20)) -> İptal ve iade süreçleri | J20: =IF(L20="","",INDEX(Madde_Magaza!$B$1:$I$1,MATCH(MAX(INDEX(Madde_Magaza!$B$2:$I$24,L20,0)),INDEX(Madde_Magaza!$B$2:$I$24,L20,0),0))) -> Mağaza F | L20: =IFERROR(MATCH(LARGE($S$6:$S$28,15),$S$6:$S$28,0),"") -> 20 | N20: =Madde_Listesi!B16 -> A-3.2 | O20: =COUNTIFS(Bulgular!$B$2:$B$570,N20,Bulgular!$J$2:$J$570,"İç denetim") -> 19 | P20: =COUNTIFS(Bulgular!$B$2:$B$570,N20,Bulgular!$J$2:$J$570,"Esas denetim") -> 11 | Q20: =O20+P20 -> 30 | R20: =Q20*INDEX(Ayarlar!$B$6:$B$8,MATCH(Madde_Listesi!E16,Ayarlar!$A$6:$A$8,0)) -> 45 | S20: =IF(OR($B$2="Tümü",Madde_Listesi!A16=$B$2),IF(Q20>0,R20+ROW()/10000,""),"") -> 45.002
N21: =Madde_Listesi!B17 -> A-4.1 | O21: =COUNTIFS(Bulgular!$B$2:$B$570,N21,Bulgular!$J$2:$J$570,"İç denetim") -> 5 | P21: =COUNTIFS(Bulgular!$B$2:$B$570,N21,Bulgular!$J$2:$J$570,"Esas denetim") -> 5 | Q21: =O21+P21 -> 10 | R21: =Q21*INDEX(Ayarlar!$B$6:$B$8,MATCH(Madde_Listesi!E17,Ayarlar!$A$6:$A$8,0)) -> 15 | S21: =IF(OR($B$2="Tümü",Madde_Listesi!A17=$B$2),IF(Q21>0,R21+ROW()/10000,""),"") -> 15.0021
N22: =Madde_Listesi!B18 -> P-1.1 | O22: =COUNTIFS(Bulgular!$B$2:$B$570,N22,Bulgular!$J$2:$J$570,"İç denetim") -> 21 | P22: =COUNTIFS(Bulgular!$B$2:$B$570,N22,Bulgular!$J$2:$J$570,"Esas denetim") -> 7 | Q22: =O22+P22 -> 28 | R22: =Q22*INDEX(Ayarlar!$B$6:$B$8,MATCH(Madde_Listesi!E18,Ayarlar!$A$6:$A$8,0)) -> 56 | S22: =IF(OR($B$2="Tümü",Madde_Listesi!A18=$B$2),IF(Q22>0,R22+ROW()/10000,""),"") -> 56.0022
A23: Eğitim konusu bazında toplam | N23: =Madde_Listesi!B19 -> P-1.2 | O23: =COUNTIFS(Bulgular!$B$2:$B$570,N23,Bulgular!$J$2:$J$570,"İç denetim") -> 2 | P23: =COUNTIFS(Bulgular!$B$2:$B$570,N23,Bulgular!$J$2:$J$570,"Esas denetim") -> 3 | Q23: =O23+P23 -> 5 | R23: =Q23*INDEX(Ayarlar!$B$6:$B$8,MATCH(Madde_Listesi!E19,Ayarlar!$A$6:$A$8,0)) -> 7.5 | S23: =IF(OR($B$2="Tümü",Madde_Listesi!A19=$B$2),IF(Q23>0,R23+ROW()/10000,""),"") -> 7.5023
B24: Eğitim Konusu | D24: Bulgu | E24: Ağırlıklı Skor | N24: =Madde_Listesi!B20 -> P-2.1 | O24: =COUNTIFS(Bulgular!$B$2:$B$570,N24,Bulgular!$J$2:$J$570,"İç denetim") -> 9 | P24: =COUNTIFS(Bulgular!$B$2:$B$570,N24,Bulgular!$J$2:$J$570,"Esas denetim") -> 6 | Q24: =O24+P24 -> 15 | R24: =Q24*INDEX(Ayarlar!$B$6:$B$8,MATCH(Madde_Listesi!E20,Ayarlar!$A$6:$A$8,0)) -> 22.5 | S24: =IF(OR($B$2="Tümü",Madde_Listesi!A20=$B$2),IF(Q24>0,R24+ROW()/10000,""),"") -> 22.5024
B25: Ekipman bakımı | D25: =COUNTIF(Bulgular!$G$2:$G$570,B25) -> 8 | E25: =SUMPRODUCT((Bulgular!$G$2:$G$570=B25)*((Bulgular!$F$2:$F$570="Kritik")*Ayarlar!$B$6+(Bulgular!$F$2:$F$570="Major")*Ayarlar!$B$7+(Bulgular!$F$2:$F$570="Minör")*Ayarlar!$B$8)) -> 8 | N25: =Madde_Listesi!B21 -> P-2.2 | O25: =COUNTIFS(Bulgular!$B$2:$B$570,N25,Bulgular!$J$2:$J$570,"İç denetim") -> 5 | P25: =COUNTIFS(Bulgular!$B$2:$B$570,N25,Bulgular!$J$2:$J$570,"Esas denetim") -> 6 | Q25: =O25+P25 -> 11 | R25: =Q25*INDEX(Ayarlar!$B$6:$B$8,MATCH(Madde_Listesi!E21,Ayarlar!$A$6:$A$8,0)) -> 11 | S25: =IF(OR($B$2="Tümü",Madde_Listesi!A21=$B$2),IF(Q25>0,R25+ROW()/10000,""),"") -> 11.0025
B26: Eğitim takibi | D26: =COUNTIF(Bulgular!$G$2:$G$570,B26) -> 10 | E26: =SUMPRODUCT((Bulgular!$G$2:$G$570=B26)*((Bulgular!$F$2:$F$570="Kritik")*Ayarlar!$B$6+(Bulgular!$F$2:$F$570="Major")*Ayarlar!$B$7+(Bulgular!$F$2:$F$570="Minör")*Ayarlar!$B$8)) -> 15 | N26: =Madde_Listesi!B22 -> P-3.1 | O26: =COUNTIFS(Bulgular!$B$2:$B$570,N26,Bulgular!$J$2:$J$570,"İç denetim") -> 12 | P26: =COUNTIFS(Bulgular!$B$2:$B$570,N26,Bulgular!$J$2:$J$570,"Esas denetim") -> 3 | Q26: =O26+P26 -> 15 | R26: =Q26*INDEX(Ayarlar!$B$6:$B$8,MATCH(Madde_Listesi!E22,Ayarlar!$A$6:$A$8,0)) -> 22.5 | S26: =IF(OR($B$2="Tümü",Madde_Listesi!A22=$B$2),IF(Q26>0,R26+ROW()/10000,""),"") -> 22.5026
B27: Haşere önleme | D27: =COUNTIF(Bulgular!$G$2:$G$570,B27) -> 7 | E27: =SUMPRODUCT((Bulgular!$G$2:$G$570=B27)*((Bulgular!$F$2:$F$570="Kritik")*Ayarlar!$B$6+(Bulgular!$F$2:$F$570="Major")*Ayarlar!$B$7+(Bulgular!$F$2:$F$570="Minör")*Ayarlar!$B$8)) -> 9 | N27: =Madde_Listesi!B23 -> P-3.2 | O27: =COUNTIFS(Bulgular!$B$2:$B$570,N27,Bulgular!$J$2:$J$570,"İç denetim") -> 10 | P27: =COUNTIFS(Bulgular!$B$2:$B$570,N27,Bulgular!$J$2:$J$570,"Esas denetim") -> 5 | Q27: =O27+P27 -> 15 | R27: =Q27*INDEX(Ayarlar!$B$6:$B$8,MATCH(Madde_Listesi!E23,Ayarlar!$A$6:$A$8,0)) -> 15 | S27: =IF(OR($B$2="Tümü",Madde_Listesi!A23=$B$2),IF(Q27>0,R27+ROW()/10000,""),"") -> 15.0027
B28: Kasa prosedürleri | D28: =COUNTIF(Bulgular!$G$2:$G$570,B28) -> 39 | E28: =SUMPRODUCT((Bulgular!$G$2:$G$570=B28)*((Bulgular!$F$2:$F$570="Kritik")*Ayarlar!$B$6+(Bulgular!$F$2:$F$570="Major")*Ayarlar!$B$7+(Bulgular!$F$2:$F$570="Minör")*Ayarlar!$B$8)) -> 75.5 | N28: =Madde_Listesi!B24 -> P-4.1 | O28: =COUNTIFS(Bulgular!$B$2:$B$570,N28,Bulgular!$J$2:$J$570,"İç denetim") -> 7 | P28: =COUNTIFS(Bulgular!$B$2:$B$570,N28,Bulgular!$J$2:$J$570,"Esas denetim") -> 2 | Q28: =O28+P28 -> 9 | R28: =Q28*INDEX(Ayarlar!$B$6:$B$8,MATCH(Madde_Listesi!E24,Ayarlar!$A$6:$A$8,0)) -> 13.5 | S28: =IF(OR($B$2="Tümü",Madde_Listesi!A24=$B$2),IF(Q28>0,R28+ROW()/10000,""),"") -> 13.5028
B29: Kimyasal güvenliği | D29: =COUNTIF(Bulgular!$G$2:$G$570,B29) -> 18 | E29: =SUMPRODUCT((Bulgular!$G$2:$G$570=B29)*((Bulgular!$F$2:$F$570="Kritik")*Ayarlar!$B$6+(Bulgular!$F$2:$F$570="Major")*Ayarlar!$B$7+(Bulgular!$F$2:$F$570="Minör")*Ayarlar!$B$8)) -> 27
B30: Kişisel hijyen | D30: =COUNTIF(Bulgular!$G$2:$G$570,B30) -> 11 | E30: =SUMPRODUCT((Bulgular!$G$2:$G$570=B30)*((Bulgular!$F$2:$F$570="Kritik")*Ayarlar!$B$6+(Bulgular!$F$2:$F$570="Major")*Ayarlar!$B$7+(Bulgular!$F$2:$F$570="Minör")*Ayarlar!$B$8)) -> 16.5
B31: Mağaza güvenliği | D31: =COUNTIF(Bulgular!$G$2:$G$570,B31) -> 30 | E31: =SUMPRODUCT((Bulgular!$G$2:$G$570=B31)*((Bulgular!$F$2:$F$570="Kritik")*Ayarlar!$B$6+(Bulgular!$F$2:$F$570="Major")*Ayarlar!$B$7+(Bulgular!$F$2:$F$570="Minör")*Ayarlar!$B$8)) -> 37.5
B32: Mağaza standartları | D32: =COUNTIF(Bulgular!$G$2:$G$570,B32) -> 8 | E32: =SUMPRODUCT((Bulgular!$G$2:$G$570=B32)*((Bulgular!$F$2:$F$570="Kritik")*Ayarlar!$B$6+(Bulgular!$F$2:$F$570="Major")*Ayarlar!$B$7+(Bulgular!$F$2:$F$570="Minör")*Ayarlar!$B$8)) -> 8
B33: Soğuk zincir ve sıcaklık kontrolü | D33: =COUNTIF(Bulgular!$G$2:$G$570,B33) -> 36 | E33: =SUMPRODUCT((Bulgular!$G$2:$G$570=B33)*((Bulgular!$F$2:$F$570="Kritik")*Ayarlar!$B$6+(Bulgular!$F$2:$F$570="Major")*Ayarlar!$B$7+(Bulgular!$F$2:$F$570="Minör")*Ayarlar!$B$8)) -> 57
B34: Stok ve sipariş yönetimi | D34: =COUNTIF(Bulgular!$G$2:$G$570,B34) -> 39 | E34: =SUMPRODUCT((Bulgular!$G$2:$G$570=B34)*((Bulgular!$F$2:$F$570="Kritik")*Ayarlar!$B$6+(Bulgular!$F$2:$F$570="Major")*Ayarlar!$B$7+(Bulgular!$F$2:$F$570="Minör")*Ayarlar!$B$8)) -> 58.5
B35: Temizlik ve dezenfeksiyon | D35: =COUNTIF(Bulgular!$G$2:$G$570,B35) -> 7 | E35: =SUMPRODUCT((Bulgular!$G$2:$G$570=B35)*((Bulgular!$F$2:$F$570="Kritik")*Ayarlar!$B$6+(Bulgular!$F$2:$F$570="Major")*Ayarlar!$B$7+(Bulgular!$F$2:$F$570="Minör")*Ayarlar!$B$8)) -> 9.5
B36: Vardiya planlama | D36: =COUNTIF(Bulgular!$G$2:$G$570,B36) -> 16 | E36: =SUMPRODUCT((Bulgular!$G$2:$G$570=B36)*((Bulgular!$F$2:$F$570="Kritik")*Ayarlar!$B$6+(Bulgular!$F$2:$F$570="Major")*Ayarlar!$B$7+(Bulgular!$F$2:$F$570="Minör")*Ayarlar!$B$8)) -> 24
B37: Ürün hazırlama standartları | D37: =COUNTIF(Bulgular!$G$2:$G$570,B37) -> 2 | E37: =SUMPRODUCT((Bulgular!$G$2:$G$570=B37)*((Bulgular!$F$2:$F$570="Kritik")*Ayarlar!$B$6+(Bulgular!$F$2:$F$570="Major")*Ayarlar!$B$7+(Bulgular!$F$2:$F$570="Minör")*Ayarlar!$B$8)) -> 3
B38: Ürün tarihleme ve etiketleme | D38: =COUNTIF(Bulgular!$G$2:$G$570,B38) -> 12 | E38: =SUMPRODUCT((Bulgular!$G$2:$G$570=B38)*((Bulgular!$F$2:$F$570="Kritik")*Ayarlar!$B$6+(Bulgular!$F$2:$F$570="Major")*Ayarlar!$B$7+(Bulgular!$F$2:$F$570="Minör")*Ayarlar!$B$8)) -> 24
B39: İptal ve iade süreçleri | D39: =COUNTIF(Bulgular!$G$2:$G$570,B39) -> 26 | E39: =SUMPRODUCT((Bulgular!$G$2:$G$570=B39)*((Bulgular!$F$2:$F$570="Kritik")*Ayarlar!$B$6+(Bulgular!$F$2:$F$570="Major")*Ayarlar!$B$7+(Bulgular!$F$2:$F$570="Minör")*Ayarlar!$B$8)) -> 33.5

Sheet Madde_Magaza
A1: Madde \ Mağaza | B1: =Magazalar!A2 -> Mağaza A | C1: =Magazalar!A3 -> Mağaza B | D1: =Magazalar!A4 -> Mağaza C | E1: =Magazalar!A5 -> Mağaza D | F1: =Magazalar!A6 -> Mağaza E | G1: =Magazalar!A7 -> Mağaza F | H1: =Magazalar!A8 -> Mağaza G | I1: =Magazalar!A9 -> Mağaza H | J1: Toplam
A2: =Madde_Listesi!B2 -> R-1.2 | B2: =COUNTIFS(Bulgular!$B$2:$B$570,$A2,Bulgular!$H$2:$H$570,B$1) -> 0 | C2: =COUNTIFS(Bulgular!$B$2:$B$570,$A2,Bulgular!$H$2:$H$570,C$1) -> 0 | D2: =COUNTIFS(Bulgular!$B$2:$B$570,$A2,Bulgular!$H$2:$H$570,D$1) -> 2 | E2: =COUNTIFS(Bulgular!$B$2:$B$570,$A2,Bulgular!$H$2:$H$570,E$1) -> 5 | F2: =COUNTIFS(Bulgular!$B$2:$B$570,$A2,Bulgular!$H$2:$H$570,F$1) -> 1 | G2: =COUNTIFS(Bulgular!$B$2:$B$570,$A2,Bulgular!$H$2:$H$570,G$1) -> 1 | H2: =COUNTIFS(Bulgular!$B$2:$B$570,$A2,Bulgular!$H$2:$H$570,H$1) -> 2 | I2: =COUNTIFS(Bulgular!$B$2:$B$570,$A2,Bulgular!$H$2:$H$570,I$1) -> 0 | J2: =SUM(B2:I2) -> 11
A3: =Madde_Listesi!B3 -> R-2.1 | B3: =COUNTIFS(Bulgular!$B$2:$B$570,$A3,Bulgular!$H$2:$H$570,B$1) -> 2 | C3: =COUNTIFS(Bulgular!$B$2:$B$570,$A3,Bulgular!$H$2:$H$570,C$1) -> 1 | D3: =COUNTIFS(Bulgular!$B$2:$B$570,$A3,Bulgular!$H$2:$H$570,D$1) -> 1 | E3: =COUNTIFS(Bulgular!$B$2:$B$570,$A3,Bulgular!$H$2:$H$570,E$1) -> 0 | F3: =COUNTIFS(Bulgular!$B$2:$B$570,$A3,Bulgular!$H$2:$H$570,F$1) -> 0 | G3: =COUNTIFS(Bulgular!$B$2:$B$570,$A3,Bulgular!$H$2:$H$570,G$1) -> 0 | H3: =COUNTIFS(Bulgular!$B$2:$B$570,$A3,Bulgular!$H$2:$H$570,H$1) -> 1 | I3: =COUNTIFS(Bulgular!$B$2:$B$570,$A3,Bulgular!$H$2:$H$570,I$1) -> 1 | J3: =SUM(B3:I3) -> 6
A4: =Madde_Listesi!B4 -> R-2.2 | B4: =COUNTIFS(Bulgular!$B$2:$B$570,$A4,Bulgular!$H$2:$H$570,B$1) -> 2 | C4: =COUNTIFS(Bulgular!$B$2:$B$570,$A4,Bulgular!$H$2:$H$570,C$1) -> 5 | D4: =COUNTIFS(Bulgular!$B$2:$B$570,$A4,Bulgular!$H$2:$H$570,D$1) -> 3 | E4: =COUNTIFS(Bulgular!$B$2:$B$570,$A4,Bulgular!$H$2:$H$570,E$1) -> 1 | F4: =COUNTIFS(Bulgular!$B$2:$B$570,$A4,Bulgular!$H$2:$H$570,F$1) -> 3 | G4: =COUNTIFS(Bulgular!$B$2:$B$570,$A4,Bulgular!$H$2:$H$570,G$1) -> 8 | H4: =COUNTIFS(Bulgular!$B$2:$B$570,$A4,Bulgular!$H$2:$H$570,H$1) -> 4 | I4: =COUNTIFS(Bulgular!$B$2:$B$570,$A4,Bulgular!$H$2:$H$570,I$1) -> 4 | J4: =SUM(B4:I4) -> 30
A5: =Madde_Listesi!B5 -> R-3.1 | B5: =COUNTIFS(Bulgular!$B$2:$B$570,$A5,Bulgular!$H$2:$H$570,B$1) -> 1 | C5: =COUNTIFS(Bulgular!$B$2:$B$570,$A5,Bulgular!$H$2:$H$570,C$1) -> 0 | D5: =COUNTIFS(Bulgular!$B$2:$B$570,$A5,Bulgular!$H$2:$H$570,D$1) -> 1 | E5: =COUNTIFS(Bulgular!$B$2:$B$570,$A5,Bulgular!$H$2:$H$570,E$1) -> 1 | F5: =COUNTIFS(Bulgular!$B$2:$B$570,$A5,Bulgular!$H$2:$H$570,F$1) -> 0 | G5: =COUNTIFS(Bulgular!$B$2:$B$570,$A5,Bulgular!$H$2:$H$570,G$1) -> 0 | H5: =COUNTIFS(Bulgular!$B$2:$B$570,$A5,Bulgular!$H$2:$H$570,H$1) -> 1 | I5: =COUNTIFS(Bulgular!$B$2:$B$570,$A5,Bulgular!$H$2:$H$570,I$1) -> 0 | J5: =SUM(B5:I5) -> 4
A6: =Madde_Listesi!B6 -> R-3.2 | B6: =COUNTIFS(Bulgular!$B$2:$B$570,$A6,Bulgular!$H$2:$H$570,B$1) -> 1 | C6: =COUNTIFS(Bulgular!$B$2:$B$570,$A6,Bulgular!$H$2:$H$570,C$1) -> 1 | D6: =COUNTIFS(Bulgular!$B$2:$B$570,$A6,Bulgular!$H$2:$H$570,D$1) -> 0 | E6: =COUNTIFS(Bulgular!$B$2:$B$570,$A6,Bulgular!$H$2:$H$570,E$1) -> 0 | F6: =COUNTIFS(Bulgular!$B$2:$B$570,$A6,Bulgular!$H$2:$H$570,F$1) -> 0 | G6: =COUNTIFS(Bulgular!$B$2:$B$570,$A6,Bulgular!$H$2:$H$570,G$1) -> 0 | H6: =COUNTIFS(Bulgular!$B$2:$B$570,$A6,Bulgular!$H$2:$H$570,H$1) -> 0 | I6: =COUNTIFS(Bulgular!$B$2:$B$570,$A6,Bulgular!$H$2:$H$570,I$1) -> 1 | J6: =SUM(B6:I6) -> 3
A7: =Madde_Listesi!B7 -> R-4.1 | B7: =COUNTIFS(Bulgular!$B$2:$B$570,$A7,Bulgular!$H$2:$H$570,B$1) -> 3 | C7: =COUNTIFS(Bulgular!$B$2:$B$570,$A7,Bulgular!$H$2:$H$570,C$1) -> 0 | D7: =COUNTIFS(Bulgular!$B$2:$B$570,$A7,Bulgular!$H$2:$H$570,D$1) -> 1 | E7: =COUNTIFS(Bulgular!$B$2:$B$570,$A7,Bulgular!$H$2:$H$570,E$1) -> 1 | F7: =COUNTIFS(Bulgular!$B$2:$B$570,$A7,Bulgular!$H$2:$H$570,F$1) -> 1 | G7: =COUNTIFS(Bulgular!$B$2:$B$570,$A7,Bulgular!$H$2:$H$570,G$1) -> 2 | H7: =COUNTIFS(Bulgular!$B$2:$B$570,$A7,Bulgular!$H$2:$H$570,H$1) -> 1 | I7: =COUNTIFS(Bulgular!$B$2:$B$570,$A7,Bulgular!$H$2:$H$570,I$1) -> 3 | J7: =SUM(B7:I7) -> 12
A8: =Madde_Listesi!B8 -> R-4.2 | B8: =COUNTIFS(Bulgular!$B$2:$B$570,$A8,Bulgular!$H$2:$H$570,B$1) -> 1 | C8: =COUNTIFS(Bulgular!$B$2:$B$570,$A8,Bulgular!$H$2:$H$570,C$1) -> 0 | D8: =COUNTIFS(Bulgular!$B$2:$B$570,$A8,Bulgular!$H$2:$H$570,D$1) -> 0 | E8: =COUNTIFS(Bulgular!$B$2:$B$570,$A8,Bulgular!$H$2:$H$570,E$1) -> 2 | F8: =COUNTIFS(Bulgular!$B$2:$B$570,$A8,Bulgular!$H$2:$H$570,F$1) -> 1 | G8: =COUNTIFS(Bulgular!$B$2:$B$570,$A8,Bulgular!$H$2:$H$570,G$1) -> 0 | H8: =COUNTIFS(Bulgular!$B$2:$B$570,$A8,Bulgular!$H$2:$H$570,H$1) -> 0 | I8: =COUNTIFS(Bulgular!$B$2:$B$570,$A8,Bulgular!$H$2:$H$570,I$1) -> 1 | J8: =SUM(B8:I8) -> 5
A9: =Madde_Listesi!B9 -> R-4.3 | B9: =COUNTIFS(Bulgular!$B$2:$B$570,$A9,Bulgular!$H$2:$H$570,B$1) -> 3 | C9: =COUNTIFS(Bulgular!$B$2:$B$570,$A9,Bulgular!$H$2:$H$570,C$1) -> 1 | D9: =COUNTIFS(Bulgular!$B$2:$B$570,$A9,Bulgular!$H$2:$H$570,D$1) -> 5 | E9: =COUNTIFS(Bulgular!$B$2:$B$570,$A9,Bulgular!$H$2:$H$570,E$1) -> 1 | F9: =COUNTIFS(Bulgular!$B$2:$B$570,$A9,Bulgular!$H$2:$H$570,F$1) -> 2 | G9: =COUNTIFS(Bulgular!$B$2:$B$570,$A9,Bulgular!$H$2:$H$570,G$1) -> 3 | H9: =COUNTIFS(Bulgular!$B$2:$B$570,$A9,Bulgular!$H$2:$H$570,H$1) -> 0 | I9: =COUNTIFS(Bulgular!$B$2:$B$570,$A9,Bulgular!$H$2:$H$570,I$1) -> 3 | J9: =SUM(B9:I9) -> 18
A10: =Madde_Listesi!B10 -> R-4.4 | B10: =COUNTIFS(Bulgular!$B$2:$B$570,$A10,Bulgular!$H$2:$H$570,B$1) -> 0 | C10: =COUNTIFS(Bulgular!$B$2:$B$570,$A10,Bulgular!$H$2:$H$570,C$1) -> 0 | D10: =COUNTIFS(Bulgular!$B$2:$B$570,$A10,Bulgular!$H$2:$H$570,D$1) -> 0 | E10: =COUNTIFS(Bulgular!$B$2:$B$570,$A10,Bulgular!$H$2:$H$570,E$1) -> 1 | F10: =COUNTIFS(Bulgular!$B$2:$B$570,$A10,Bulgular!$H$2:$H$570,F$1) -> 0 | G10: =COUNTIFS(Bulgular!$B$2:$B$570,$A10,Bulgular!$H$2:$H$570,G$1) -> 0 | H10: =COUNTIFS(Bulgular!$B$2:$B$570,$A10,Bulgular!$H$2:$H$570,H$1) -> 1 | I10: =COUNTIFS(Bulgular!$B$2:$B$570,$A10,Bulgular!$H$2:$H$570,I$1) -> 0 | J10: =SUM(B10:I10) -> 2
A11: =Madde_Listesi!B11 -> A-1.1 | B11: =COUNTIFS(Bulgular!$B$2:$B$570,$A11,Bulgular!$H$2:$H$570,B$1) -> 1 | C11: =COUNTIFS(Bulgular!$B$2:$B$570,$A11,Bulgular!$H$2:$H$570,C$1) -> 2 | D11: =COUNTIFS(Bulgular!$B$2:$B$570,$A11,Bulgular!$H$2:$H$570,D$1) -> 0 | E11: =COUNTIFS(Bulgular!$B$2:$B$570,$A11,Bulgular!$H$2:$H$570,E$1) -> 2 | F11: =COUNTIFS(Bulgular!$B$2:$B$570,$A11,Bulgular!$H$2:$H$570,F$1) -> 2 | G11: =COUNTIFS(Bulgular!$B$2:$B$570,$A11,Bulgular!$H$2:$H$570,G$1) -> 2 | H11: =COUNTIFS(Bulgular!$B$2:$B$570,$A11,Bulgular!$H$2:$H$570,H$1) -> 5 | I11: =COUNTIFS(Bulgular!$B$2:$B$570,$A11,Bulgular!$H$2:$H$570,I$1) -> 2 | J11: =SUM(B11:I11) -> 16
A12: =Madde_Listesi!B12 -> A-1.2 | B12: =COUNTIFS(Bulgular!$B$2:$B$570,$A12,Bulgular!$H$2:$H$570,B$1) -> 0 | C12: =COUNTIFS(Bulgular!$B$2:$B$570,$A12,Bulgular!$H$2:$H$570,C$1) -> 2 | D12: =COUNTIFS(Bulgular!$B$2:$B$570,$A12,Bulgular!$H$2:$H$570,D$1) -> 1 | E12: =COUNTIFS(Bulgular!$B$2:$B$570,$A12,Bulgular!$H$2:$H$570,E$1) -> 0 | F12: =COUNTIFS(Bulgular!$B$2:$B$570,$A12,Bulgular!$H$2:$H$570,F$1) -> 1 | G12: =COUNTIFS(Bulgular!$B$2:$B$570,$A12,Bulgular!$H$2:$H$570,G$1) -> 2 | H12: =COUNTIFS(Bulgular!$B$2:$B$570,$A12,Bulgular!$H$2:$H$570,H$1) -> 0 | I12: =COUNTIFS(Bulgular!$B$2:$B$570,$A12,Bulgular!$H$2:$H$570,I$1) -> 0 | J12: =SUM(B12:I12) -> 6
A13: =Madde_Listesi!B13 -> A-2.1 | B13: =COUNTIFS(Bulgular!$B$2:$B$570,$A13,Bulgular!$H$2:$H$570,B$1) -> 1 | C13: =COUNTIFS(Bulgular!$B$2:$B$570,$A13,Bulgular!$H$2:$H$570,C$1) -> 1 | D13: =COUNTIFS(Bulgular!$B$2:$B$570,$A13,Bulgular!$H$2:$H$570,D$1) -> 1 | E13: =COUNTIFS(Bulgular!$B$2:$B$570,$A13,Bulgular!$H$2:$H$570,E$1) -> 0 | F13: =COUNTIFS(Bulgular!$B$2:$B$570,$A13,Bulgular!$H$2:$H$570,F$1) -> 0 | G13: =COUNTIFS(Bulgular!$B$2:$B$570,$A13,Bulgular!$H$2:$H$570,G$1) -> 3 | H13: =COUNTIFS(Bulgular!$B$2:$B$570,$A13,Bulgular!$H$2:$H$570,H$1) -> 1 | I13: =COUNTIFS(Bulgular!$B$2:$B$570,$A13,Bulgular!$H$2:$H$570,I$1) -> 1 | J13: =SUM(B13:I13) -> 8
... A24: =Madde_Listesi!B24 -> P-4.1 | B24: =COUNTIFS(Bulgular!$B$2:$B$570,$A24,Bulgular!$H$2:$H$570,B$1) -> 0 | C24: =COUNTIFS(Bulgular!$B$2:$B$570,$A24,Bulgular!$H$2:$H$570,C$1) -> 0 | D24: =COUNTIFS(Bulgular!$B$2:$B$570,$A24,Bulgular!$H$2:$H$570,D$1) -> 0 | E24: =COUNTIFS(Bulgular!$B$2:$B$570,$A24,Bulgular!$H$2:$H$570,E$1) -> 3 | F24: =COUNTIFS(Bulgular!$B$2:$B$570,$A24,Bulgular!$H$2:$H$570,F$1) -> 1 | G24: =COUNTIFS(Bulgular!$B$2:$B$570,$A24,Bulgular!$H$2:$H$570,G$1) -> 2 | H24: =COUNTIFS(Bulgular!$B$2:$B$570,$A24,Bulgular!$H$2:$H$570,H$1) -> 3 | I24: =COUNTIFS(Bulgular!$B$2:$B$570,$A24,Bulgular!$H$2:$H$570,I$1) -> 0 | J24: =SUM(B24:I24) -> 9
A25: Toplam | B25: =SUM(B2:B24) -> 27 | C25: =SUM(C2:C24) -> 21 | D25: =SUM(D2:D24) -> 28 | E25: =SUM(E2:E24) -> 38 | F25: =SUM(F2:F24) -> 27 | G25: =SUM(G2:G24) -> 44 | H25: =SUM(H2:H24) -> 44 | I25: =SUM(I2:I24) -> 40 | J25: =SUM(J2:J24) -> 269

Sheet Denetim_Takvimi
A1: Denetim Takvimi
A2: İç denetim rotasyonu (çeyreklik) — denetçi, denetim türünde uzman olan ve mümkünse aynı yakınlık grubundaki mağazanın müdürüdür.
A4: Çeyrek | B4: Denetlenen Mağaza | C4: Denetim Türü | D4: Denetçi (Mağaza Müdürü) | E4: Planlanan Tarih | F4: Gerçekleşen Tarih | G4: Durum | H4: Rotasyon Kontrolü | J4: Tahmini Esas Denetimler
A5: 2026-Ç1 | B5: Mağaza A | C5: ASA | D5: Mağaza B | E5: 46051 | F5: 46052 | G5: =IF(F5<>"","Yapıldı",IF(E5<Ayarlar!$B$3,"Gecikti",IF(E5-Ayarlar!$B$3<=Ayarlar!$B$15,"Yaklaşıyor","Planlandı"))) -> Yapıldı | H5: =IF(B5=D5,"Kendi mağazası!",IF(INDEX(Magazalar!$C:$C,MATCH(D5,Magazalar!$A:$A,0))<>C5,"Uzmanlık dışı",IF(INDEX(Magazalar!$B:$B,MATCH(D5,Magazalar!$A:$A,0))<>INDEX(Magazalar!$B:$B,MATCH(B5,Magazalar!$A:$A,0)),"Uygun (grup dışı)","Uygun"))) -> Uygun | J5: Mağaza | K5: Tür | L5: Tahmini Tarih | M5: Kalan Gün | N5: Durum
A6: 2026-Ç1 | B6: Mağaza A | C6: PAP | D6: Mağaza C | E6: 46061 | F6: 46061 | G6: =IF(F6<>"","Yapıldı",IF(E6<Ayarlar!$B$3,"Gecikti",IF(E6-Ayarlar!$B$3<=Ayarlar!$B$15,"Yaklaşıyor","Planlandı"))) -> Yapıldı | H6: =IF(B6=D6,"Kendi mağazası!",IF(INDEX(Magazalar!$C:$C,MATCH(D6,Magazalar!$A:$A,0))<>C6,"Uzmanlık dışı",IF(INDEX(Magazalar!$B:$B,MATCH(D6,Magazalar!$A:$A,0))<>INDEX(Magazalar!$B:$B,MATCH(B6,Magazalar!$A:$A,0)),"Uygun (grup dışı)","Uygun"))) -> Uygun | J6: Mağaza A | K6: ASA | L6: 46304 | M6: =L6-Ayarlar!$B$3 -> 25 | N6: =IF(M6<0,"Tarih geçti",IF(M6<=Ayarlar!$B$15,"Yaklaşıyor","")) -> Yaklaşıyor
A7: 2026-Ç1 | B7: Mağaza A | C7: RSA | D7: Mağaza D | E7: 46049 | F7: 46049 | G7: =IF(F7<>"","Yapıldı",IF(E7<Ayarlar!$B$3,"Gecikti",IF(E7-Ayarlar!$B$3<=Ayarlar!$B$15,"Yaklaşıyor","Planlandı"))) -> Yapıldı | H7: =IF(B7=D7,"Kendi mağazası!",IF(INDEX(Magazalar!$C:$C,MATCH(D7,Magazalar!$A:$A,0))<>C7,"Uzmanlık dışı",IF(INDEX(Magazalar!$B:$B,MATCH(D7,Magazalar!$A:$A,0))<>INDEX(Magazalar!$B:$B,MATCH(B7,Magazalar!$A:$A,0)),"Uygun (grup dışı)","Uygun"))) -> Uygun (grup dışı) | J7: Mağaza A | K7: PAP | L7: 46418 | M7: =L7-Ayarlar!$B$3 -> 139 | N7: =IF(M7<0,"Tarih geçti",IF(M7<=Ayarlar!$B$15,"Yaklaşıyor",""))
A8: 2026-Ç1 | B8: Mağaza B | C8: ASA | D8: Mağaza G | E8: 46042 | F8: 46042 | G8: =IF(F8<>"","Yapıldı",IF(E8<Ayarlar!$B$3,"Gecikti",IF(E8-Ayarlar!$B$3<=Ayarlar!$B$15,"Yaklaşıyor","Planlandı"))) -> Yapıldı | H8: =IF(B8=D8,"Kendi mağazası!",IF(INDEX(Magazalar!$C:$C,MATCH(D8,Magazalar!$A:$A,0))<>C8,"Uzmanlık dışı",IF(INDEX(Magazalar!$B:$B,MATCH(D8,Magazalar!$A:$A,0))<>INDEX(Magazalar!$B:$B,MATCH(B8,Magazalar!$A:$A,0)),"Uygun (grup dışı)","Uygun"))) -> Uygun (grup dışı) | J8: Mağaza A | K8: RSA | L8: 46446 | M8: =L8-Ayarlar!$B$3 -> 167 | N8: =IF(M8<0,"Tarih geçti",IF(M8<=Ayarlar!$B$15,"Yaklaşıyor",""))
A9: 2026-Ç1 | B9: Mağaza B | C9: PAP | D9: Mağaza C | E9: 46052 | F9: 46050 | G9: =IF(F9<>"","Yapıldı",IF(E9<Ayarlar!$B$3,"Gecikti",IF(E9-Ayarlar!$B$3<=Ayarlar!$B$15,"Yaklaşıyor","Planlandı"))) -> Yapıldı | H9: =IF(B9=D9,"Kendi mağazası!",IF(INDEX(Magazalar!$C:$C,MATCH(D9,Magazalar!$A:$A,0))<>C9,"Uzmanlık dışı",IF(INDEX(Magazalar!$B:$B,MATCH(D9,Magazalar!$A:$A,0))<>INDEX(Magazalar!$B:$B,MATCH(B9,Magazalar!$A:$A,0)),"Uygun (grup dışı)","Uygun"))) -> Uygun | J9: Mağaza B | K9: ASA | L9: 46359 | M9: =L9-Ayarlar!$B$3 -> 80 | N9: =IF(M9<0,"Tarih geçti",IF(M9<=Ayarlar!$B$15,"Yaklaşıyor",""))
A10: 2026-Ç1 | B10: Mağaza B | C10: RSA | D10: Mağaza A | E10: 46050 | F10: 46053 | G10: =IF(F10<>"","Yapıldı",IF(E10<Ayarlar!$B$3,"Gecikti",IF(E10-Ayarlar!$B$3<=Ayarlar!$B$15,"Yaklaşıyor","Planlandı"))) -> Yapıldı | H10: =IF(B10=D10,"Kendi mağazası!",IF(INDEX(Magazalar!$C:$C,MATCH(D10,Magazalar!$A:$A,0))<>C10,"Uzmanlık dışı",IF(INDEX(Magazalar!$B:$B,MATCH(D10,Magazalar!$A:$A,0))<>INDEX(Magazalar!$B:$B,MATCH(B10,Magazalar!$A:$A,0)),"Uygun (grup dışı)","Uygun"))) -> Uygun | J10: Mağaza B | K10: PAP | L10: 46342 | M10: =L10-Ayarlar!$B$3 -> 63 | N10: =IF(M10<0,"Tarih geçti",IF(M10<=Ayarlar!$B$15,"Yaklaşıyor",""))
A11: 2026-Ç1 | B11: Mağaza C | C11: ASA | D11: Mağaza B | E11: 46078 | F11: 46078 | G11: =IF(F11<>"","Yapıldı",IF(E11<Ayarlar!$B$3,"Gecikti",IF(E11-Ayarlar!$B$3<=Ayarlar!$B$15,"Yaklaşıyor","Planlandı"))) -> Yapıldı | H11: =IF(B11=D11,"Kendi mağazası!",IF(INDEX(Magazalar!$C:$C,MATCH(D11,Magazalar!$A:$A,0))<>C11,"Uzmanlık dışı",IF(INDEX(Magazalar!$B:$B,MATCH(D11,Magazalar!$A:$A,0))<>INDEX(Magazalar!$B:$B,MATCH(B11,Magazalar!$A:$A,0)),"Uygun (grup dışı)","Uygun"))) -> Uygun | J11: Mağaza B | K11: RSA | L11: 46245 | M11: =L11-Ayarlar!$B$3 -> -34 | N11: =IF(M11<0,"Tarih geçti",IF(M11<=Ayarlar!$B$15,"Yaklaşıyor","")) -> Tarih geçti
A12: 2026-Ç1 | B12: Mağaza C | C12: PAP | D12: Mağaza F | E12: 46066 | F12: 46069 | G12: =IF(F12<>"","Yapıldı",IF(E12<Ayarlar!$B$3,"Gecikti",IF(E12-Ayarlar!$B$3<=Ayarlar!$B$15,"Yaklaşıyor","Planlandı"))) -> Yapıldı | H12: =IF(B12=D12,"Kendi mağazası!",IF(INDEX(Magazalar!$C:$C,MATCH(D12,Magazalar!$A:$A,0))<>C12,"Uzmanlık dışı",IF(INDEX(Magazalar!$B:$B,MATCH(D12,Magazalar!$A:$A,0))<>INDEX(Magazalar!$B:$B,MATCH(B12,Magazalar!$A:$A,0)),"Uygun (grup dışı)","Uygun"))) -> Uygun (grup dışı) | J12: Mağaza C | K12: ASA | L12: 46381 | M12: =L12-Ayarlar!$B$3 -> 102 | N12: =IF(M12<0,"Tarih geçti",IF(M12<=Ayarlar!$B$15,"Yaklaşıyor",""))
A13: 2026-Ç1 | B13: Mağaza C | C13: RSA | D13: Mağaza A | E13: 46066 | F13: 46069 | G13: =IF(F13<>"","Yapıldı",IF(E13<Ayarlar!$B$3,"Gecikti",IF(E13-Ayarlar!$B$3<=Ayarlar!$B$15,"Yaklaşıyor","Planlandı"))) -> Yapıldı | H13: =IF(B13=D13,"Kendi mağazası!",IF(INDEX(Magazalar!$C:$C,MATCH(D13,Magazalar!$A:$A,0))<>C13,"Uzmanlık dışı",IF(INDEX(Magazalar!$B:$B,MATCH(D13,Magazalar!$A:$A,0))<>INDEX(Magazalar!$B:$B,MATCH(B13,Magazalar!$A:$A,0)),"Uygun (grup dışı)","Uygun"))) -> Uygun | J13: Mağaza C | K13: PAP | L13: 46255 | M13: =L13-Ayarlar!$B$3 -> -24 | N13: =IF(M13<0,"Tarih geçti",IF(M13<=Ayarlar!$B$15,"Yaklaşıyor","")) -> Tarih geçti
A14: 2026-Ç1 | B14: Mağaza D | C14: ASA | D14: Mağaza E | E14: 46068 | F14: 46066 | G14: =IF(F14<>"","Yapıldı",IF(E14<Ayarlar!$B$3,"Gecikti",IF(E14-Ayarlar!$B$3<=Ayarlar!$B$15,"Yaklaşıyor","Planlandı"))) -> Yapıldı | H14: =IF(B14=D14,"Kendi mağazası!",IF(INDEX(Magazalar!$C:$C,MATCH(D14,Magazalar!$A:$A,0))<>C14,"Uzmanlık dışı",IF(INDEX(Magazalar!$B:$B,MATCH(D14,Magazalar!$A:$A,0))<>INDEX(Magazalar!$B:$B,MATCH(B14,Magazalar!$A:$A,0)),"Uygun (grup dışı)","Uygun"))) -> Uygun | J14: Mağaza C | K14: RSA | L14: 46284 | M14: =L14-Ayarlar!$B$3 -> 5 | N14: =IF(M14<0,"Tarih geçti",IF(M14<=Ayarlar!$B$15,"Yaklaşıyor","")) -> Yaklaşıyor
A15: 2026-Ç1 | B15: Mağaza D | C15: PAP | D15: Mağaza F | E15: 46049 | F15: 46052 | G15: =IF(F15<>"","Yapıldı",IF(E15<Ayarlar!$B$3,"Gecikti",IF(E15-Ayarlar!$B$3<=Ayarlar!$B$15,"Yaklaşıyor","Planlandı"))) -> Yapıldı | H15: =IF(B15=D15,"Kendi mağazası!",IF(INDEX(Magazalar!$C:$C,MATCH(D15,Magazalar!$A:$A,0))<>C15,"Uzmanlık dışı",IF(INDEX(Magazalar!$B:$B,MATCH(D15,Magazalar!$A:$A,0))<>INDEX(Magazalar!$B:$B,MATCH(B15,Magazalar!$A:$A,0)),"Uygun (grup dışı)","Uygun"))) -> Uygun | J15: Mağaza D | K15: ASA | L15: 46305 | M15: =L15-Ayarlar!$B$3 -> 26 | N15: =IF(M15<0,"Tarih geçti",IF(M15<=Ayarlar!$B$15,"Yaklaşıyor","")) -> Yaklaşıyor
A16: 2026-Ç1 | B16: Mağaza D | C16: RSA | D16: Mağaza H | E16: 46042 | F16: 46045 | G16: =IF(F16<>"","Yapıldı",IF(E16<Ayarlar!$B$3,"Gecikti",IF(E16-Ayarlar!$B$3<=Ayarlar!$B$15,"Yaklaşıyor","Planlandı"))) -> Yapıldı | H16: =IF(B16=D16,"Kendi mağazası!",IF(INDEX(Magazalar!$C:$C,MATCH(D16,Magazalar!$A:$A,0))<>C16,"Uzmanlık dışı",IF(INDEX(Magazalar!$B:$B,MATCH(D16,Magazalar!$A:$A,0))<>INDEX(Magazalar!$B:$B,MATCH(B16,Magazalar!$A:$A,0)),"Uygun (grup dışı)","Uygun"))) -> Uygun (grup dışı) | J16: Mağaza D | K16: PAP | L16: 46255 | M16: =L16-Ayarlar!$B$3 -> -24 | N16: =IF(M16<0,"Tarih geçti",IF(M16<=Ayarlar!$B$15,"Yaklaşıyor","")) -> Tarih geçti
A17: 2026-Ç1 | B17: Mağaza E | C17: ASA | D17: Mağaza B | E17: 46051 | F17: 46051 | G17: =IF(F17<>"","Yapıldı",IF(E17<Ayarlar!$B$3,"Gecikti",IF(E17-Ayarlar!$B$3<=Ayarlar!$B$15,"Yaklaşıyor","Planlandı"))) -> Yapıldı | H17: =IF(B17=D17,"Kendi mağazası!",IF(INDEX(Magazalar!$C:$C,MATCH(D17,Magazalar!$A:$A,0))<>C17,"Uzmanlık dışı",IF(INDEX(Magazalar!$B:$B,MATCH(D17,Magazalar!$A:$A,0))<>INDEX(Magazalar!$B:$B,MATCH(B17,Magazalar!$A:$A,0)),"Uygun (grup dışı)","Uygun"))) -> Uygun (grup dışı) | J17: Mağaza D | K17: RSA | L17: 46450 | M17: =L17-Ayarlar!$B$3 -> 171 | N17: =IF(M17<0,"Tarih geçti",IF(M17<=Ayarlar!$B$15,"Yaklaşıyor",""))
... A29: 2026-Ç2 | B29: Mağaza A | C29: ASA | D29: Mağaza B | E29: 46140 | F29: 46138 | G29: =IF(F29<>"","Yapıldı",IF(E29<Ayarlar!$B$3,"Gecikti",IF(E29-Ayarlar!$B$3<=Ayarlar!$B$15,"Yaklaşıyor","Planlandı"))) -> Yapıldı | H29: =IF(B29=D29,"Kendi mağazası!",IF(INDEX(Magazalar!$C:$C,MATCH(D29,Magazalar!$A:$A,0))<>C29,"Uzmanlık dışı",IF(INDEX(Magazalar!$B:$B,MATCH(D29,Magazalar!$A:$A,0))<>INDEX(Magazalar!$B:$B,MATCH(B29,Magazalar!$A:$A,0)),"Uygun (grup dışı)","Uygun"))) -> Uygun | J29: Mağaza H | K29: RSA | L29: 46237 | M29: =L29-Ayarlar!$B$3 -> -42 | N29: =IF(M29<0,"Tarih geçti",IF(M29<=Ayarlar!$B$15,"Yaklaşıyor","")) -> Tarih geçti
A30: 2026-Ç2 | B30: Mağaza A | C30: PAP | D30: Mağaza C | E30: 46136 | F30: 46134 | G30: =IF(F30<>"","Yapıldı",IF(E30<Ayarlar!$B$3,"Gecikti",IF(E30-Ayarlar!$B$3<=Ayarlar!$B$15,"Yaklaşıyor","Planlandı"))) -> Yapıldı | H30: =IF(B30=D30,"Kendi mağazası!",IF(INDEX(Magazalar!$C:$C,MATCH(D30,Magazalar!$A:$A,0))<>C30,"Uzmanlık dışı",IF(INDEX(Magazalar!$B:$B,MATCH(D30,Magazalar!$A:$A,0))<>INDEX(Magazalar!$B:$B,MATCH(B30,Magazalar!$A:$A,0)),"Uygun (grup dışı)","Uygun"))) -> Uygun
A31: 2026-Ç2 | B31: Mağaza A | C31: RSA | D31: Mağaza H | E31: 46131 | F31: 46129 | G31: =IF(F31<>"","Yapıldı",IF(E31<Ayarlar!$B$3,"Gecikti",IF(E31-Ayarlar!$B$3<=Ayarlar!$B$15,"Yaklaşıyor","Planlandı"))) -> Yapıldı | H31: =IF(B31=D31,"Kendi mağazası!",IF(INDEX(Magazalar!$C:$C,MATCH(D31,Magazalar!$A:$A,0))<>C31,"Uzmanlık dışı",IF(INDEX(Magazalar!$B:$B,MATCH(D31,Magazalar!$A:$A,0))<>INDEX(Magazalar!$B:$B,MATCH(B31,Magazalar!$A:$A,0)),"Uygun (grup dışı)","Uygun"))) -> Uygun (grup dışı)
